Workbook
Name ________A100000: #REF!
Name ________A100000: #REF!
Name ________A99999: #REF!
Name ________A99999: #REF!
Name _______A100000: #REF!
Name _______A100000: #REF!
Name _______A99999: #REF!
Name _______A99999: #REF!
Name _______Man1: [1]PaintBreak!$M$55
Name _______Man22: [1]PaintBreak!$M$56
Name _______Mat1: [1]PaintBreak!$K$55
Name _______Mat2: [1]PaintBreak!$K$56
Name ______A100000: #REF!
Name ______A100000: #REF!
Name ______A99999: #REF!
Name ______A99999: #REF!
Name ______Man1: [1]PaintBreak!$M$55
Name ______Man22: [1]PaintBreak!$M$56
Name ______Mat1: [1]PaintBreak!$K$55
Name ______Mat2: [1]PaintBreak!$K$56
Name _____A100000: #REF!
Name _____A100000: #REF!
Name _____A99999: #REF!
Name _____A99999: #REF!
Name _____Man1: [2]PaintBreak!$M$55
Name _____Man22: [2]PaintBreak!$M$56
Name _____Mat1: [2]PaintBreak!$K$55
Name _____Mat2: [2]PaintBreak!$K$56
Name ____A100000: #REF!
Name ____A100000: #REF!
Name ____A99999: #REF!
Name ____A99999: #REF!
Name ____Man1: [2]PaintBreak!$M$55
Name ____Man22: [2]PaintBreak!$M$56
Name ____Mat1: [2]PaintBreak!$K$55
Name ____Mat2: [2]PaintBreak!$K$56
Name ____UPA100: '[3]GTS I PS'!#REF!
Name ____UPA100: '[3]GTS I PS'!#REF!
Name ___A100000: #REF!
Name ___A100000: #REF!
Name ___A99999: #REF!
Name ___A99999: #REF!
Name ___FIL1: 'Cover Report'!___FIL1
Name ___FIL1: 'Exe Sum'!___FIL1
Name ___FIL1: [0]!___FIL1
Name ___Man1: [2]PaintBreak!$M$55
Name ___Man22: [2]PaintBreak!$M$56
Name ___Mat1: [2]PaintBreak!$K$55
Name ___Mat2: [2]PaintBreak!$K$56
Name ___UPA100: '[3]GTS I PS'!#REF!
Name ___UPA100: '[3]GTS I PS'!#REF!
Name __A100000: #REF!
Name __A100000: #REF!
Name __A99999: #REF!
Name __A99999: #REF!
Name __FIL1: 'Cover Report'!__FIL1
Name __FIL1: 'Exe Sum'!__FIL1
Name __FIL1: [0]!__FIL1
Name __Man1: [2]PaintBreak!$M$55
Name __Man22: [2]PaintBreak!$M$56

Sheet Cover Report
X1: Project Title | Y1: : | Z1: Integrated Management Dashboard Production & Project Zona 13
I2: DOCUMENT REPORT | U2: Up Date Every Week | X2: Doc Name | Y2: : | Z2: W2026I-DNGF-EM-100-PRG-WLY
B3: Project Title Integrated Management Dashboard Production & Project Zona 13 | K3: Document No. | L3: : | M3: =Z5 -> W2026I-DNGF-EM-100-PRG-WLY-0012 | X3: Doc No | Y3: : | Z3: 12
B4: Contract Number 901407233 | K4: SPK/ CTR Title | L4: : | M4: - | X4: Doc-togle | Y4: : | Z4: 0000
B5: Author's Organization Project | K5: Period | L5: : | M5: =Z10 -> 29 Juni 2026 - 05 Juli 2026 | X5: Doc-Concate | Y5: : | Z5: =CONCATENATE(Z2,"-",TEXT(Z3,Z4)) -> W2026I-DNGF-EM-100-PRG-WLY-0012
K6: Revision No. | L6: : | M6: 0 | N6: Date | O6: : | P6: =Z9 -> 46208
X8: Start Period | Y8: : | Z8: =HLOOKUP((Z3-1),'Overall MDR_'!BM11:CH12,2,FALSE)+1 -> 46202
X9: End Period | Y9: : | Z9: =HLOOKUP(Z3,'Overall MDR_'!BM11:CH12,2,FALSE) -> 46208
X10: Period-Concate | Y10: : | Z10: =TEXT(Z8,"dd mmmm yyyy")&" - "&TEXT(Z9,"dd mmmm yyyy") -> 29 Juni 2026 - 05 Juli 2026
I11: WEEKLY REPORT
C12: Integrated Management Dashboard Production & Project Zona 13
C16: Approval Sheet
C17: Name | I17: Tittle | L17: Date | O17: Signature
C18: Wahyudi | I18: Manager Project PEP Zona 13
C19: Seno Widjojo | I19: Sr Engineer Project & Safety
C20: Andik Yuli Wahyono | I20: Sr Engineer Construction
C21: Erikson Juanda Panjaitan | I21: Sr Engineer Project Economics & Risk
C22: Nyoman Ading Widiartama | I22: Sr Project Budget & Cost Control PEP Zona 13
C23: Bambang Saefu | I23: Sr Engineering Project Planning & Schedulling
C24: Abdurahmman Hadiwijaya | I24: Sr. Engineer Project Contract Management PEP Zona 13
C29: Revision Status
C30: Rev | D30: Issue Date | H30: ITS PTN BH | L30: Issue Porpose
H31: Prepared | J31: Checked | K31: Approved
C32: 0 | D32: =P6 -> 46208 | H32: AR | J32: BS | K32: ES | L32: Issued for Information

Sheet TOC
E1: PERTAMINA EP
E3: Project Title : | K3: Document Number :
E4: ='Cover Report'!Z1 -> Integrated Management Dashboard Production & Project Zona 13 | K4: ='Cover Report'!Z5 -> W2026I-DNGF-EM-100-PRG-WLY-0012
E5: Document Title: | K5: Page ii
E6: Weekly Report
A9: Table of Content
B11: Cover | M11: i
B12: Table of Content | M12: ii
B13: Executive Summary | M13: iii
B14: Area of Concern / Issues and Mitigation Plan | M14: iii
B15: Master Deliverable Register | M15: iii
B16: Document Issued in This Week 01
B18: Appendices
B19: Appendix A | C19: Project S-Curve
B20: Appendix B | C20: Master Deliverable Register
B21: Appendix C | C21: Document Submitted in Week 01
B22: Appendix D | C22: Activity Documentation
G187: ELECTRICAL & INSTRUMENTATION ENGINEERING (as of 2 October)
O267: 0.9176 | P267: 0.8494
P268: 1
O274: 0.9121 | P274: 0.8934
P275: 0.685

Sheet Exe Sum
E1: =TOC!E1 -> PERTAMINA EP
E3: Project Title : | O3: Document Number : | Y3: Doc | Z3: : | AA3: ='Cover Report'!Z3 -> 12 | AL3: Previous | AQ3: This Week | AV3: To Date
E4: =TOC!E4 -> Integrated Management Dashboard Production & Project Zona 13 | O4: ='Cover Report'!Z5 -> W2026I-DNGF-EM-100-PRG-WLY-0012 | Y4: Project Name | Z4: : | AA4: ='Cover Report'!Z1 -> Integrated Management Dashboard Production & Project Zona 13 | AL4: Plan | AM4: Recovery | AN4: Actual | AO4: Variance | AP4: Variance to Recovery | AQ4: Plan | AR4: Recovery | AS4: Actual | AT4: Variance | AU4: Variance to Recovery | AV4: Plan | AW4: Recovery | AX4: Actual | AY4: Variance | AZ4: Variance to Recovery
E5: Document Title: | O5: Page iii | Y5: Start Date | Z5: : | AA5: ='Cover Report'!Z8 -> 46202 | AK5: 1 | AL5: {=_xlfn._xlws.FILTER('Overall MDR_'!BM50:CH50,'Overall MDR_'!BM$11:CH$11=('Exe Sum'!$AA$3-1))} -> 1 | AM5: {=_xlfn._xlws.FILTER('Overall MDR_'!CL50:DG50,'Overall MDR_'!CL$11:DG$11=('Exe Sum'!$AA$3-1))} -> 0 | AN5: {=_xlfn._xlws.FILTER('Overall MDR_'!DL50:EG50,'Overall MDR_'!DL$11:EG$11=('Exe Sum'!$AA$3-1))} -> 1 | AO5: =AN5-AL5 -> 0 | AP5: =AN5-AM5 -> 1 | AQ5: =AV5-AL5 -> 0 | AR5: =AW5-AM5 -> 0 | AS5: =AX5-AN5 -> 0 | AT5: =AS5-AQ5 -> 0 | AU5: =AS5-AR5 -> 0 | AV5: {=_xlfn._xlws.FILTER('Overall MDR_'!BM50:CH50,'Overall MDR_'!BM$11:CH$11=('Exe Sum'!$AA$3))} -> 1 | AW5: {=_xlfn._xlws.FILTER('Overall MDR_'!CL50:DG50,'Overall MDR_'!CL$11:DG$11=('Exe Sum'!$AA$3))} -> 0 | AX5: {=_xlfn._xlws.FILTER('Overall MDR_'!DL50:EG50,'Overall MDR_'!DL$11:EG$11=('Exe Sum'!$AA$3))} -> 1 | AY5: =AX5-AV5 -> 0 | AZ5: =AX5-AW5 -> 1
E6: =TOC!E6 -> Weekly Report | Y6: End Date | Z6: : | AA6: ='Cover Report'!Z9 -> 46208 | AK6: 2 | AL6: {=_xlfn._xlws.FILTER('Overall MDR_'!BM51:CH51,'Overall MDR_'!BM$11:CH$11=('Exe Sum'!$AA$3-1))} -> 1 | AM6: {=_xlfn._xlws.FILTER('Overall MDR_'!CL51:DG51,'Overall MDR_'!CL$11:DG$11=('Exe Sum'!$AA$3-1))} -> 0 | AN6: {=_xlfn._xlws.FILTER('Overall MDR_'!DL51:EG51,'Overall MDR_'!DL$11:EG$11=('Exe Sum'!$AA$3-1))} -> 0 | AO6: =AN6-AL6 -> -1 | AP6: =AN6-AM6 -> 0 | AQ6: =AV6-AL6 -> 0 | AR6: =AW6-AM6 -> 0 | AS6: =AX6-AN6 -> 0 | AT6: =AS6-AQ6 -> 0 | AU6: =AS6-AR6 -> 0 | AV6: {=_xlfn._xlws.FILTER('Overall MDR_'!BM51:CH51,'Overall MDR_'!BM$11:CH$11=('Exe Sum'!$AA$3))} -> 1 | AW6: {=_xlfn._xlws.FILTER('Overall MDR_'!CL51:DG51,'Overall MDR_'!CL$11:DG$11=('Exe Sum'!$AA$3))} -> 0 | AX6: {=_xlfn._xlws.FILTER('Overall MDR_'!DL51:EG51,'Overall MDR_'!DL$11:EG$11=('Exe Sum'!$AA$3))} -> 0 | AY6: =AX6-AV6 -> -1 | AZ6: =AX6-AW6 -> 0
Y7: Progress Plan | Z7: : | AA7: =O29 -> 0.85975 | AK7: 3 | AL7: {=_xlfn._xlws.FILTER('Overall MDR_'!BM52:CH52,'Overall MDR_'!BM$11:CH$11=('Exe Sum'!$AA$3-1))} -> 0.97475476 | AM7: {=_xlfn._xlws.FILTER('Overall MDR_'!CL52:DG52,'Overall MDR_'!CL$11:DG$11=('Exe Sum'!$AA$3-1))} -> 0 | AN7: {=_xlfn._xlws.FILTER('Overall MDR_'!DL52:EG52,'Overall MDR_'!DL$11:EG$11=('Exe Sum'!$AA$3-1))} -> 1 | AO7: =AN7-AL7 -> 0.025245239 | AP7: =AN7-AM7 -> 1 | AQ7: =AV7-AL7 -> 0.025245239 | AR7: =AW7-AM7 -> 0 | AS7: =AX7-AN7 -> 0 | AT7: =AS7-AQ7 -> -0.025245239 | AU7: =AS7-AR7 -> 0 | AV7: {=_xlfn._xlws.FILTER('Overall MDR_'!BM52:CH52,'Overall MDR_'!BM$11:CH$11=('Exe Sum'!$AA$3))} -> 1 | AW7: {=_xlfn._xlws.FILTER('Overall MDR_'!CL52:DG52,'Overall MDR_'!CL$11:DG$11=('Exe Sum'!$AA$3))} -> 0 | AX7: {=_xlfn._xlws.FILTER('Overall MDR_'!DL52:EG52,'Overall MDR_'!DL$11:EG$11=('Exe Sum'!$AA$3))} -> 1 | AY7: =AX7-AV7 -> 0 | AZ7: =AX7-AW7 -> 1
Y8: Actual Plan | Z8: : | AA8: =Q29 -> 0.8667 | AK8: 4 | AL8: {=_xlfn._xlws.FILTER('Overall MDR_'!BM53:CH53,'Overall MDR_'!BM$11:CH$11=('Exe Sum'!$AA$3-1))} -> 1 | AM8: {=_xlfn._xlws.FILTER('Overall MDR_'!CL53:DG53,'Overall MDR_'!CL$11:DG$11=('Exe Sum'!$AA$3-1))} -> 0 | AN8: {=_xlfn._xlws.FILTER('Overall MDR_'!DL53:EG53,'Overall MDR_'!DL$11:EG$11=('Exe Sum'!$AA$3-1))} -> 1 | AO8: =AN8-AL8 -> 0 | AP8: =AN8-AM8 -> 1 | AQ8: =AV8-AL8 -> 0 | AR8: =AW8-AM8 -> 0 | AS8: =AX8-AN8 -> 0 | AT8: =AS8-AQ8 -> 0 | AU8: =AS8-AR8 -> 0 | AV8: {=_xlfn._xlws.FILTER('Overall MDR_'!BM53:CH53,'Overall MDR_'!BM$11:CH$11=('Exe Sum'!$AA$3))} -> 1 | AW8: {=_xlfn._xlws.FILTER('Overall MDR_'!CL53:DG53,'Overall MDR_'!CL$11:DG$11=('Exe Sum'!$AA$3))} -> 0 | AX8: {=_xlfn._xlws.FILTER('Overall MDR_'!DL53:EG53,'Overall MDR_'!DL$11:EG$11=('Exe Sum'!$AA$3))} -> 1 | AY8: =AX8-AV8 -> 0 | AZ8: =AX8-AW8 -> 1
A9: Executive Summary | Y9: Variance | Z9: : | AA9: =R29 -> 0.00695 | AK9: 5 | AL9: {=_xlfn._xlws.FILTER('Overall MDR_'!BM54:CH54,'Overall MDR_'!BM$11:CH$11=('Exe Sum'!$AA$3-1))} -> 0.83333333 | AM9: {=_xlfn._xlws.FILTER('Overall MDR_'!CL54:DG54,'Overall MDR_'!CL$11:DG$11=('Exe Sum'!$AA$3-1))} -> 0.16666667 | AN9: {=_xlfn._xlws.FILTER('Overall MDR_'!DL54:EG54,'Overall MDR_'!DL$11:EG$11=('Exe Sum'!$AA$3-1))} -> 1 | AO9: =AN9-AL9 -> 0.16666667 | AP9: =AN9-AM9 -> 0.83333333 | AQ9: =AV9-AL9 -> 0.16666667 | AR9: =AW9-AM9 -> 0 | AS9: =AX9-AN9 -> 0 | AT9: =AS9-AQ9 -> -0.16666667 | AU9: =AS9-AR9 -> 0 | AV9: {=_xlfn._xlws.FILTER('Overall MDR_'!BM54:CH54,'Overall MDR_'!BM$11:CH$11=('Exe Sum'!$AA$3))} -> 1 | AW9: {=_xlfn._xlws.FILTER('Overall MDR_'!CL54:DG54,'Overall MDR_'!CL$11:DG$11=('Exe Sum'!$AA$3))} -> 0.16666667 | AX9: {=_xlfn._xlws.FILTER('Overall MDR_'!DL54:EG54,'Overall MDR_'!DL$11:EG$11=('Exe Sum'!$AA$3))} -> 1 | AY9: =AX9-AV9 -> 0 | AZ9: =AX9-AW9 -> 0.83333333
Y10: Recovery | Z10: : | AA10: ='Overall MDR_'!BJ38 -> 0.0309 | AK10: 6 | AL10: {=_xlfn._xlws.FILTER('Overall MDR_'!BM55:CH55,'Overall MDR_'!BM$11:CH$11=('Exe Sum'!$AA$3-1))} -> 0.3244145 | AM10: {=_xlfn._xlws.FILTER('Overall MDR_'!CL55:DG55,'Overall MDR_'!CL$11:DG$11=('Exe Sum'!$AA$3-1))} -> 0 | AN10: {=_xlfn._xlws.FILTER('Overall MDR_'!DL55:EG55,'Overall MDR_'!DL$11:EG$11=('Exe Sum'!$AA$3-1))} -> 0.55004812 | AO10: =AN10-AL10 -> 0.22563362 | AP10: =AN10-AM10 -> 0.55004812 | AQ10: =AV10-AL10 -> 0.22563362 | AR10: =AW10-AM10 -> 0 | AS10: =AX10-AN10 -> 0.18752005 | AT10: =AS10-AQ10 -> -0.038113571 | AU10: =AS10-AR10 -> 0.18752005 | AV10: {=_xlfn._xlws.FILTER('Overall MDR_'!BM55:CH55,'Overall MDR_'!BM$11:CH$11=('Exe Sum'!$AA$3))} -> 0.55004812 | AW10: {=_xlfn._xlws.FILTER('Overall MDR_'!CL55:DG55,'Overall MDR_'!CL$11:DG$11=('Exe Sum'!$AA$3))} -> 0 | AX10: {=_xlfn._xlws.FILTER('Overall MDR_'!DL55:EG55,'Overall MDR_'!DL$11:EG$11=('Exe Sum'!$AA$3))} -> 0.73756817 | AY10: =AX10-AV10 -> 0.18752005 | AZ10: =AX10-AW10 -> 0.73756817
A11: 1. | B11: Executive Summary
B12: =AA14&" "&AA15&" "&AA16&" "&AA17&" "&AA18 -> Integrated Management Dashboard Production & Project Zona 13 progress this week (cut-off date : 05 Juli 2026) : planned cumulative progress plan is 85.98% against the actual cumulative progress of 86.67%. The progress for this week is behind the schedule 3.09%
Y13: Exe sum
AA14: =AA4 -> Integrated Management Dashboard Production & Project Zona 13
B15: The detailed breakdown of the discipline weekly summary is presented in the following table. | AA15: ="progress this week (cut-off date : "&TEXT(AA6,"dd mmmm yyyy")&") : " -> progress this week (cut-off date : 05 Juli 2026) :
AA16: ="planned cumulative progress plan is "&TEXT(AA7,"0.00%") -> planned cumulative progress plan is 85.98%
B17: Table 1.1 Discipline Weekly Summary | AA17: ="against the actual cumulative progress of "&TEXT(AA8,"0.00%")&"." -> against the actual cumulative progress of 86.67%.
AA18: ="The progress for this week is behind the schedule "&TEXT(AA10,"0.00%") -> The progress for this week is behind the schedule 3.09%
B19: No | C19: Description | D19: WF | E19: Previous Week (Cumulative) | J19: This Week | O19: To Date (Cumulative) | T19: Remarks
E20: Plan | F20: Recovery | G20: Actual | H20: Variance | I20: Variance to Recovery | J20: Plan | K20: Recovery | L20: Actual | M20: Variance | N20: Variance to Recovery | O20: Plan | P20: Recovery | Q20: Actual | R20: Variance | S20: Variance to Recovery | Y20: MDR
AA21: ="See Appendix B for the full Master Deliverable Register (MDR) with updated dates as of "&TEXT(AA6,"dd mmmm yyyy") -> See Appendix B for the full Master Deliverable Register (MDR) with updated dates as of 05 Juli 2026
B22: 1 | C22: ='Overall MDR_'!C16 -> Analisis Kebutuhan | D22: ='Overall MDR_'!F16 -> 0.0927 | E22: =AL5 -> 1 | F22: =AM5 -> 0 | G22: =AN5 -> 1 | H22: =AO5 -> 0 | I22: 0 | J22: =AQ5 -> 0 | K22: =AR5 -> 0 | L22: =AS5 -> 0 | M22: =AT5 -> 0 | N22: =AU5 -> 0 | O22: =AV5 -> 1 | P22: =AW5 -> 0 | Q22: =AX5 -> 1 | R22: =AY5 -> 0 | S22: 0
B23: 2 | C23: ='Overall MDR_'!C19 -> Pengadaan | D23: ='Overall MDR_'!F19 -> 0.0515 | E23: =AL6 -> 1 | F23: =AM6 -> 0 | G23: =AN6 -> 0 | H23: =AO6 -> -1 | I23: =AP6 -> 0 | J23: =AQ6 -> 0 | K23: =AR6 -> 0 | L23: =AS6 -> 0 | ... R23: =AY6 -> -1 | S23: =Q23-P23 -> 0 | T23: Menunggu Keputsan dari Pertamina terkait dengan pengadaan Hardware
B24: 3 | C24: ='Overall MDR_'!C21 -> Desain UI/UX | D24: ='Overall MDR_'!F21 -> 0.1733 | E24: =AL7 -> 0.97475476 | F24: =AM7 -> 0 | G24: =AN7 -> 1 | H24: =AO7 -> 0.025245239 | I24: 0 | J24: =AQ7 -> 0.025245239 | K24: =AR7 -> 0 | L24: =AS7 -> 0 | M24: =AT7 -> -0.025245239 | N24: =AU7 -> 0 | O24: =AV7 -> 1 | P24: =AW7 -> 0 | Q24: =AX7 -> 1 | R24: =AY7 -> 0 | S24: 0
B25: 4 | C25: ='Overall MDR_'!C25 -> Integrasi Sumber Data; Konfigurasi database dengan sumber data; Data Connection Schema & Production Data Mapping | D25: ='Overall MDR_'!F25 -> 0.1854 | E25: =AL8 -> 1 | F25: =AM8 -> 0 | G25: =AN8 -> 1 | H25: =AO8 -> 0 | I25: 0 | J25: =AQ8 -> 0 | K25: =AR8 -> 0 | L25: =AS8 -> 0 | M25: =AT8 -> 0 | N25: =AU8 -> 0 | O25: =AV8 -> 1 | P25: =AW8 -> 0 | Q25: =AX8 -> 1 | R25: =AY8 -> 0 | S25: 0
B26: 5 | C26: ='Overall MDR_'!C29 -> Persiapan Data (ETL) | D26: ='Overall MDR_'!F29 -> 0.1854 | E26: =AL9 -> 0.83333333 | F26: 0 | G26: =AN9 -> 1 | H26: =AO9 -> 0.16666667 | I26: 0 | J26: =AQ9 -> 0.16666667 | K26: =AR9 -> 0 | L26: =AS9 -> 0 | M26: =AT9 -> -0.16666667 | N26: =AU9 -> 0 | O26: =AV9 -> 1 | P26: 0 | Q26: =AX9 -> 1 | R26: =AY9 -> 0 | S26: 0
B27: 6 | C27: ='Overall MDR_'!C32 -> Pengembangan Dashboard | D27: ='Overall MDR_'!F32 -> 0.3117 | E27: =AL10 -> 0.3244145 | F27: =AM10 -> 0 | G27: =AN10 -> 0.55004812 | H27: =AO10 -> 0.22563362 | I27: 0 | J27: =AQ10 -> 0.22563362 | K27: =AR10 -> 0 | L27: =AS10 -> 0.18752005 | M27: =AT10 -> -0.038113571 | N27: 0 | O27: =AV10 -> 0.55004812 | P27: =AW10 -> 0 | Q27: =AX10 -> 0.73756817 | R27: =AY10 -> 0.18752005 | S27: 0 | T27: Menunggu Keputsan dari Pertamina untuk kelanjutannya
C29: Overall | D29: =SUM(D22:D27) -> 1 | E29: {=SUMPRODUCT($D$22:$D$27*E$22:E$27)} -> 0.754145 | F29: {=SUMPRODUCT(D22:D27*F22:F27)} -> 0 | G29: {=SUMPRODUCT(D22:D27*G22:G27)} -> 0.80825 | H29: {=SUMPRODUCT($D$22:$D$27*H$22:H$27)} -> 0.054105 | I29: {=SUMPRODUCT(D22:D27*I22:I27)} -> 0 | J29: {=SUMPRODUCT($D$22:$D$27*J$22:J$27)} -> 0.105605 | K29: {=SUMPRODUCT(D22:D27*K22:K27)} -> 0 | L29: {=SUMPRODUCT($D$22:$D$27*L$22:L$27)} -> 0.05845 | M29: {=SUMPRODUCT($D$22:$D$27*M$22:M$27)} -> -0.047155 | N29: {=SUMPRODUCT(D22:D27*N22:N27)} -> 0 | O29: {=SUMPRODUCT($D$22:$D$27*O$22:O$27)} -> 0.85975 | P29: {=SUMPRODUCT(D22:D27*P22:P27)} -> 0 | Q29: {=SUMPRODUCT($D$22:$D$27*Q$22:Q$27)} -> 0.8667 | R29: {=SUMPRODUCT($D$22:$D$27*R$22:R$27)} -> 0.00695 | S29: {=SUMPRODUCT(D22:D27*S22:S27)} -> 0
B30: * | C30: The S-Curve can be seen in Appendix-A
A32: 2. | B32: Area of Concern / Issues and Mitigation Plan
B33: 1. Pertamina dapat mulai melakukan review terhadap dashboard yang telah dikembangkan oleh ITS 2. Dokumen 6d sedang dalam review oleh Pak Seno. 3. Data AIRMS dan I2AIMS yang digunakan di modul OSF adalah data dummy. Jika terdapat data yang baru disampaikan, dapat di lakukan pada fase berikutnya (Post Implementation). 4. Untuk modul Project, saat ini masih ada contoh NBD (Project dengan ITS), untuk contoh Project BD belum ada.
A35: 3. | B35: Master Deliverable Register
B36: =AA21 -> See Appendix B for the full Master Deliverable Register (MDR) with updated dates as of 05 Juli 2026
A38: 4. | B38: Document Issued in This Week
B39: Week | C39: =": "&AA3 -> : 12
B40: Start Date | C40: =": "&TEXT(AA5,"dd mmmm yyyy") -> : 29 Juni 2026
B41: End Date | C41: =": "&TEXT(AA6,"dd mmmm yyyy") -> : 05 Juli 2026
B42: The list submitted document is provided in Appendix C
H167: ELECTRICAL & INSTRUMENTATION ENGINEERING (as of 2 October)
U247: 0.9176 | V247: 0.8494
V248: 1
...

Sheet Appendix A
D1: =TOC!E1 -> PERTAMINA EP
D3: Project Title : | L3: Document Number :
D4: ='Cover Report'!Z1 -> Integrated Management Dashboard Production & Project Zona 13 | L4: ='Cover Report'!Z5 -> W2026I-DNGF-EM-100-PRG-WLY-0012
D5: Document Title: | L5: Appendix A
D6: =TOC!E6 -> Weekly Report
A27: APPENDIX A
A29: PROJECT S-CURVE
R269: ELECTRICAL & INSTRUMENTATION ENGINEERING (as of 2 October)
J278: ELECTRICAL & INSTRUMENTATION ENGINEERING (as of 2 October)
AF349: 0.9176 | AG349: 0.8494
AG350: 1
AF356: 0.9121 | AG356: 0.8934
AG357: 0.685

Sheet S-Overall
A1: ITS PTN BH
A2: S - CURVE - OVERALL
A4: CLIENT | B4: : | C4: PT Pertamina EP
A5: PROJECT | B5: : | C5: ='Cover Report'!Z1 -> Integrated Management Dashboard Production & Project Zona 13
A6: WO Ttile. | B6: : | C6: ='Cover Report'!Z2 -> W2026I-DNGF-EM-100-PRG-WLY
A7: WO No. | B7: : | C7: ='Cover Report'!Z5 -> W2026I-DNGF-EM-100-PRG-WLY-0012
AP12: ='Overall MDR_'!BM11 -> 0 | AQ12: ='Overall MDR_'!BN11 -> 0 | AR12: ='Overall MDR_'!BO11 -> 1 | AS12: ='Overall MDR_'!BP11 -> 2 | AT12: ='Overall MDR_'!BQ11 -> 3 | AU12: ='Overall MDR_'!BR11 -> 4 | AV12: ='Overall MDR_'!BS11 -> 5 | AW12: ='Overall MDR_'!BT11 -> 6 | ... BK12: ='Overall MDR_'!CH11 -> 20
AP13: ='Overall MDR_'!BM12 -> 46113 | AQ13: ='Overall MDR_'!BN12 -> 46124 | AR13: ='Overall MDR_'!BO12 -> 46131 | AS13: ='Overall MDR_'!BP12 -> 46138 | AT13: ='Overall MDR_'!BQ12 -> 46145 | AU13: ='Overall MDR_'!BR12 -> 46152 | AV13: ='Overall MDR_'!BS12 -> 46159 | AW13: ='Overall MDR_'!BT12 -> 46166 | ... BK13: ='Overall MDR_'!CH12 -> 46265
AN14: =A64 -> ACTUAL THIS WEEK | AP14: =AP15 -> 0 | AQ14: =AQ15-AP15 -> 0.217725 | AR14: =AR15-AQ15 -> 0.144065 | AS14: =AS15-AR15 -> 0.05701 | AT14: =AT15-AS15 -> 0.01876 | AU14: =AU15-AT15 -> 0.01545 | AV14: =AV15-AU15 -> 0.05959 | AW14: =AW15-AV15 -> 0.009425 | AX14: =AX15-AW15 -> 0.030885 | ... BC14: =BC15-BB15 -> 0.05845
AN15: =A65 -> ACTUAL CUMMULATIVE | AP15: ='Overall MDR_'!DL47 -> 0 | AQ15: ='Overall MDR_'!DM47 -> 0.217725 | AR15: ='Overall MDR_'!DN47 -> 0.36179 | AS15: ='Overall MDR_'!DO47 -> 0.4188 | AT15: ='Overall MDR_'!DP47 -> 0.43756 | AU15: ='Overall MDR_'!DQ47 -> 0.45301 | AV15: ='Overall MDR_'!DR47 -> 0.5126 | AW15: ='Overall MDR_'!DS47 -> 0.522025 | ... BC15: ='Overall MDR_'!DY47 -> 0.8667
AN16: =A66 -> PLAN THIS WEEK | AP16: =AP17 -> 0 | AQ16: =AQ17-AP17 -> 0.063355 | AR16: =AR17-AQ17 -> 0.03709 | AS16: =AS17-AR17 -> 0.07108 | AT16: =AT17-AS17 -> 0.042595 | AU16: =AU17-AT17 -> 0.04895 | AV16: =AV17-AU17 -> 0.12258 | AW16: =AW17-AV17 -> 0.088225 | AX16: =AX17-AW17 -> 0.084175 | ... BK16: =BK17-BJ17 -> 0
AN17: =A67 -> PLAN CUMMULATIVE | AP17: ='Overall MDR_'!BM47 -> 0 | AQ17: ='Overall MDR_'!BN47 -> 0.063355 | AR17: ='Overall MDR_'!BO47 -> 0.100445 | AS17: ='Overall MDR_'!BP47 -> 0.171525 | AT17: ='Overall MDR_'!BQ47 -> 0.21412 | AU17: ='Overall MDR_'!BR47 -> 0.26307 | AV17: ='Overall MDR_'!BS47 -> 0.38565 | AW17: ='Overall MDR_'!BT47 -> 0.473875 | ... BK17: ='Overall MDR_'!CH47 -> 1
AN18: =A68 -> Recovery | AP18: ='Overall MDR_'!CL47 -> 0 | AQ18: ='Overall MDR_'!CM47 -> 0 | AR18: ='Overall MDR_'!CN47 -> 0 | AS18: ='Overall MDR_'!CO47 -> 0.0309 | AT18: ='Overall MDR_'!CP47 -> 0.0309 | AU18: ='Overall MDR_'!CQ47 -> 0.0309 | AV18: ='Overall MDR_'!CR47 -> 0.0309 | AW18: ='Overall MDR_'!CS47 -> 0.0309 | ... BC18: ='Overall MDR_'!CY47 -> 0.0309
AN19: =A69 -> VARIANCE TO Recovery | AP19: =AP15-AP18 -> 0 | AQ19: =AQ15-AQ18 -> 0.217725 | AR19: =AR15-AR18 -> 0.36179 | AS19: =AS15-AS18 -> 0.3879 | AT19: =AT15-AT18 -> 0.40666 | AU19: =AU15-AU18 -> 0.42211 | AV19: =AV15-AV18 -> 0.4817 | AW19: =AW15-AW18 -> 0.491125 | ... BC19: =BC15-BC18 -> 0.8358
AN20: =A70 -> VARIANCE TO PLAN | AP20: =AP15-AP17 -> 0 | AQ20: =AQ15-AQ17 -> 0.15437 | AR20: =AR15-AR17 -> 0.261345 | AS20: =AS15-AS17 -> 0.247275 | AT20: =AT15-AT17 -> 0.22344 | AU20: =AU15-AU17 -> 0.18994 | AV20: =AV15-AV17 -> 0.12695 | AW20: =AW15-AW17 -> 0.04815 | ... BC20: =BC15-BC17 -> 0.00695
D24: OPF Balongan - Adequacy Check
A58: DESCRIPTION | C58: =AP12 -> 0 | D58: =AQ12 -> 0 | E58: =AR12 -> 1 | F58: =AS12 -> 2 | G58: =AT12 -> 3 | H58: =AU12 -> 4 | I58: =AV12 -> 5 | J58: =AW12 -> 6 | ... X58: =BK12 -> 20
C59: =AP13 -> 46113 | D59: =AQ13 -> 46124 | E59: =AR13 -> 46131 | F59: =AS13 -> 46138 | G59: =AT13 -> 46145 | H59: =AU13 -> 46152 | I59: =AV13 -> 46159 | J59: =AW13 -> 46166 | ... X59: =BK13 -> 46265
A63: PLANNED | C63: 0 | D63: 0 | E63: 0 | F63: 0.03949962 | G63: 1.0394996 | H63: 1.0394996 | I63: 1.0394996 | J63: 1.0394996 | K63: 1.0394996 | L63: 1.0394996 | M63: 1.0394996 | N63: 1.0394996 | O63: 1.0394996 | P63: 1.0394996 | Q63: 1.0394996 | R63: 1.0394996 | S63: 1.0394996 | T63: 1.0394996 | U63: 1.0394996 | V63: 1.0394996 | W63: 1.0394996 | X63: 1.0394996
A64: ACTUAL THIS WEEK | C64: =AP14 -> 0 | D64: =AQ14 -> 0.217725 | E64: =AR14 -> 0.144065 | F64: =AS14 -> 0.05701 | G64: =AT14 -> 0.01876 | H64: =AU14 -> 0.01545 | I64: =AV14 -> 0.05959 | J64: =AW14 -> 0.009425 | ... P64: =BC14 -> 0.05845
A65: ACTUAL CUMMULATIVE | C65: =AP15 -> 0 | D65: =AQ15 -> 0.217725 | E65: =AR15 -> 0.36179 | F65: =AS15 -> 0.4188 | G65: =AT15 -> 0.43756 | H65: =AU15 -> 0.45301 | I65: =AV15 -> 0.5126 | J65: =AW15 -> 0.522025 | ... P65: =BC15 -> 0.8667
A66: PLAN THIS WEEK | C66: =AP16 -> 0 | D66: =AQ16 -> 0.063355 | E66: =AR16 -> 0.03709 | F66: =AS16 -> 0.07108 | G66: =AT16 -> 0.042595 | H66: =AU16 -> 0.04895 | I66: =AV16 -> 0.12258 | J66: =AW16 -> 0.088225 | ... X66: =BK16 -> 0
A67: PLAN CUMMULATIVE | C67: =AP17 -> 0 | D67: =AQ17 -> 0.063355 | E67: =AR17 -> 0.100445 | F67: =AS17 -> 0.171525 | G67: =AT17 -> 0.21412 | H67: =AU17 -> 0.26307 | I67: =AV17 -> 0.38565 | J67: =AW17 -> 0.473875 | ... X67: =BK17 -> 1
A68: Recovery | C68: =AP18 -> 0 | D68: 0 | E68: 0 | F68: 0 | G68: 0 | H68: 0 | I68: 0 | J68: 0 | K68: 0 | L68: 0 | M68: 0 | N68: 0 | O68: 0 | P68: 0
A69: VARIANCE TO Recovery | C69: =AP19 -> 0 | D69: 0 | E69: 0 | F69: 0 | G69: 0 | H69: 0 | I69: 0 | J69: 0 | K69: 0 | L69: 0 | M69: 0 | N69: 0 | O69: 0 | P69: 0
A70: VARIANCE TO PLAN | C70: =AP20 -> 0 | D70: =AQ20 -> 0.15437 | E70: =AR20 -> 0.261345 | F70: =AS20 -> 0.247275 | G70: =AT20 -> 0.22344 | H70: =AU20 -> 0.18994 | I70: =AV20 -> 0.12695 | J70: =AW20 -> 0.04815 | ... P70: =BC20 -> 0.00695

Sheet Check
B3: Exe Sum | C3: S-Curve
A4: Previous (Cummulative)
A5: Plan | B5: ='Exe Sum'!E29 -> 0.754145 | C5: ='S-Overall'!O67 -> 0.754145 | D5: =IF(B5=C5,"Sesuai","Tidak Sesuai") -> Sesuai
A6: Aktual | B6: ='Exe Sum'!G29 -> 0.80825 | C6: ='S-Overall'!O65 -> 0.80825 | D6: =IF(B6=C6,"Sesuai","Tidak Sesuai") -> Sesuai
A7: Variance | B7: ='Exe Sum'!H29 -> 0.054105 | C7: ='S-Overall'!O70 -> 0.054105 | D7: =IF(ROUND(B7,6)=ROUND(C7,6),"Sesuai","Tidak Sesuai") -> Sesuai
A9: This Week
A10: Plan | B10: ='Exe Sum'!J29 -> 0.105605 | C10: ='S-Overall'!P66 -> 0.105605 | D10: =IF(ROUND(B10,6)=ROUND(C10,6),"Sesuai","Tidak Sesuai") -> Sesuai
A11: Aktual | B11: ='Exe Sum'!L29 -> 0.05845 | C11: ='S-Overall'!P64 -> 0.05845 | D11: =IF(ROUND(B11,6)=ROUND(C11,6),"Sesuai","Tidak Sesuai") -> Sesuai
A12: Variance | B12: ='Exe Sum'!M29 -> -0.047155 | C12: =C11-C10 -> -0.047155 | D12: =IF(ROUND(B12,6)=ROUND(C12,6),"Sesuai","Tidak Sesuai") -> Sesuai
A14: To Date (Cummulative)
A15: Plan | B15: ='Exe Sum'!O29 -> 0.85975 | C15: ='S-Overall'!P67 -> 0.85975 | D15: =IF(B15=C15,"Sesuai","Tidak Sesuai") -> Sesuai
A16: Aktual | B16: ='Exe Sum'!Q29 -> 0.8667 | C16: ='S-Overall'!P65 -> 0.8667 | D16: =IF(B16=C16,"Sesuai","Tidak Sesuai") -> Sesuai
A17: Variance | B17: ='Exe Sum'!R29 -> 0.00695 | C17: ='S-Overall'!P70 -> 0.00695 | D17: =IF(ROUND(B17,6)=ROUND(C17,6),"Sesuai","Tidak Sesuai") -> Sesuai

Sheet Appendix B
D1: =TOC!E1 -> PERTAMINA EP
D3: Project Title : | L3: Document Number :
D4: ='Cover Report'!Z1 -> Integrated Management Dashboard Production & Project Zona 13 | L4: ='Cover Report'!Z5 -> W2026I-DNGF-EM-100-PRG-WLY-0012
D5: Document Title: | L5: Appendix B
D6: =TOC!E6 -> Weekly Report
A27: APPENDIX B
A29: MASTER DELIVERABLE REGISTER (MDR)
R268: ELECTRICAL & INSTRUMENTATION ENGINEERING (as of 2 October)
J277: ELECTRICAL & INSTRUMENTATION ENGINEERING (as of 2 October)
AF348: 0.9176 | AG348: 0.8494
AG349: 1
AF355: 0.9121 | AG355: 0.8934
AG356: 0.685

Sheet Overall MDR_
J2: ENGINEERING DOCUMENTS REGISTER
B4: CLIENT | C4: : | D4: PT Pertamina EP | AN4: Rev. No. : | AO4: 0
B5: PROJECT | C5: : | D5: ='Cover Report'!Z1 -> Integrated Management Dashboard Production & Project Zona 13 | AN5: Week No. : | AO5: =BN5 -> 12 | BL5: =HLOOKUP(BN5,$BM$11:$CH$12,2,FALSE) -> 46208 | BM5: Report No. | BN5: ='Cover Report'!Z3 -> 12 | DK5: =BL5 -> 46208 | DL5: Report No. | DM5: =BN5 -> 12
B6: WO Title | C6: : | AN6: Cut-off Date : | AO6: =BL5 -> 46208 | BL6: =(HLOOKUP(BN6,$BM$11:$CH$12,2,FALSE))+1 -> 46202 | BN6: =BN5-1 -> 11 | DK6: =BL6 -> 46202 | DM6: =BN6 -> 11
B7: WO No. | C7: :
BL8: ESTIMATE PLAN CUMULATIVE REV.0 | CK8: ESTIMATE FORECAST CUMULATIVE REV.0 | DK8: ACTUAL CUMULATIVE REV.0
E9: REVISION | F9: WEIGHT FACTOR | H9: Inter-Discipline Review | K9: Rev A | O9: Rev A | S9: Rev 0 | AB9: APPROVED | AG9: PHYSICAL PROGRESS | BD9: Activity | BE9: ACTUAL | BG9: PLAN | BI9: FORECAST
K10: IFR (Issued for Review) | O10: IFR (Issued for Review) | S10: IFD (Issued for Design) | W10: Close Out Report | AE10: Progress Overall | AR10: PAYMENT PROGRESS
A11: Deliverables | H11: 0.05 | K11: 0.25 | O11: 0.5 | S11: 0.75 | W11: 1 | AG11: EACH DELIVERABLE | AN11: OVERALL | AR11: OVERALL | BE11: LAST | BF11: TODATE | BG11: LAST | BH11: TODATE | BI11: LAST | BJ11: TODATE | BN11: 0 | BO11: 1 | BP11: 2 | BQ11: 3 | BR11: 4 | BS11: 5 | BT11: 6 | BU11: 7 | BV11: 8 | BW11: 9 | BX11: 10 | BY11: 11 | BZ11: 12 | CA11: 13 | CB11: 14 | CC11: 15 | CD11: 16 | CE11: 17 | CF11: 18 | CG11: 19 | CH11: 20 | CM11: 0 | CN11: 1 | CO11: 2 | CP11: 3 | CQ11: 4 | CR11: 5 | CS11: 6 | CT11: 7 | CU11: 8 | CV11: 9 | CW11: 10 | CX11: 11 | CY11: 12 | CZ11: 13 | DA11: 14 | DB11: 15 | DC11: 16 | DD11: 17 | DE11: 18 | DF11: 19 | DG11: 20 | DM11: 0 | DN11: 1 | DO11: 2 | DP11: 3 | DQ11: 4 | DR11: 5 | DS11: 6 | DT11: 7 | DU11: 8 | DV11: 9 | DW11: 10 | DX11: 11 | DY11: 12 | DZ11: 13 | EA11: 14 | EB11: 15 | EC11: 16 | ED11: 17 | EE11: 18 | EF11: 19 | EG11: 20
H12: =H11 -> 0.05 | I12: =H11 -> 0.05 | J12: =H11 -> 0.05 | K12: =K11 -> 0.25 | L12: =K11 -> 0.25 | M12: =K11 -> 0.25 | N12: =K11 -> 0.25 | O12: =O11 -> 0.5 | P12: =O11 -> 0.5 | Q12: =O11 -> 0.5 | R12: =O11 -> 0.5 | S12: =S11 -> 0.75 | T12: =S11 -> 0.75 | U12: =S11 -> 0.75 | V12: =S11 -> 0.75 | W12: =W11 -> 1 | X12: =W11 -> 1 | Y12: =W11 -> 1 | Z12: =W11 -> 1 | AA12: =W11 -> 1 | AF12: Doc Impact | AG12: ACTUAL | AJ12: PLAN | AK12: Re-baseline | AL12: VARIANCE PLAN | AM12: VARIANCE Re-baseline | AN12: ACTUAL | AO12: PLAN | AP12: Re-baseline | AQ12: VAR | AR12: LAST WEEK | AS12: THIS WEEK | AT12: TODATE | BM12: 46113 | BN12: =BM12+11 -> 46124 | BO12: =BN12+7 -> 46131 | BP12: =BO12+7 -> 46138 | BQ12: =BP12+7 -> 46145 | BR12: =BQ12+7 -> 46152 | BS12: =BR12+7 -> 46159 | BT12: =BS12+7 -> 46166 | BU12: =BT12+7 -> 46173 | BV12: =BU12+7 -> 46180 | ... CG12: =CF12+7 -> 46257 | CH12: =CG12+8 -> 46265 | CL12: 46113 | CM12: =CL12+12 -> 46125 | CN12: =CM12+6 -> 46131 | CO12: =CN12+7 -> 46138 | CP12: =CO12+7 -> 46145 | CQ12: =CP12+7 -> 46152 | CR12: =CQ12+7 -> 46159 | CS12: =CR12+7 -> 46166 | CT12: =CS12+7 -> 46173 | CU12: =CT12+7 -> 46180 | CV12: =CU12+7 -> 46187 | ... DF12: =DE12+7 -> 46257 | DG12: =DF12+8 -> 46265 | DL12: 46113 | DM12: =DL12+12 -> 46125 | DN12: =DM12+6 -> 46131 | DO12: =DN12+7 -> 46138 | DP12: =DO12+7 -> 46145 | DQ12: =DP12+7 -> 46152 | DR12: =DQ12+7 -> 46159 | DS12: =DR12+7 -> 46166 | DT12: =DS12+7 -> 46173 | DU12: =DT12+7 -> 46180 | DV12: =DU12+7 -> 46187 | ... EF12: =EE12+7 -> 46257 | EG12: =EF12+8 -> 46265
H13: Plan | I13: Recovery | J13: Actual | K13: Plan | L13: Recovery | M13: Actual | N13: Return | O13: Plan | P13: Recovery | Q13: Actual | R13: Return | S13: Plan | T13: Recovery | U13: Actual | V13: Return | W13: Plan | X13: Recovery | Y13: Actual | Z13: Return | AA13: NOTE | AB13: Plan | AC13: Forecast | AD13: Actual | AG13: LAST | AH13: THIS WK | AI13: TODATE | AJ13: TODATE | AK13: TODATE | AL13: TODATE | AN13: TODATE | AO13: TODATE | AP13: TODATE | AQ13: TODATE | AT13: W. U .
A15: OVERALL | F15: =SUBTOTAL(9,F16:F37) -> 1 | AZ15: 0.77735 | BD15: OVERALL | BE15: =SUBTOTAL(9,BE16:BE36) -> 0.8316 | BF15: =SUBTOTAL(9,BF16:BF36) -> 0.8667 | BG15: =SUBTOTAL(9,BG16:BG36) -> 0.754145 | BH15: =SUBTOTAL(9,BH16:BH36) -> 0.85975 | BI15: =SUBTOTAL(9,BI16:BI36) -> 0.0309 | BJ15: =SUBTOTAL(9,BJ16:BJ36) -> 0.0309 | BM15: =SUBTOTAL(9,BM16:BM36) -> 0 | BN15: =SUBTOTAL(9,BN16:BN36) -> 0.063355 | BO15: =SUBTOTAL(9,BO16:BO36) -> 0.100445 | BP15: =SUBTOTAL(9,BP16:BP36) -> 0.171525 | BQ15: =SUBTOTAL(9,BQ16:BQ36) -> 0.21412 | BR15: =SUBTOTAL(9,BR16:BR36) -> 0.26307 | BS15: =SUBTOTAL(9,BS16:BS36) -> 0.38565 | BT15: =SUBTOTAL(9,BT16:BT36) -> 0.473875 | ... CH15: =SUBTOTAL(9,CH16:CH36) -> 1 | CL15: =SUBTOTAL(9,CL16:CL36) -> 0 | CM15: =SUBTOTAL(9,CM16:CM36) -> 0 | CN15: =SUBTOTAL(9,CN16:CN36) -> 0 | CO15: =SUBTOTAL(9,CO16:CO36) -> 0.0309 | CP15: =SUBTOTAL(9,CP16:CP36) -> 0.0309 | CQ15: =SUBTOTAL(9,CQ16:CQ36) -> 0.0309 | CR15: =SUBTOTAL(9,CR16:CR36) -> 0.0309 | CS15: =SUBTOTAL(9,CS16:CS36) -> 0.0309 | ... DG15: =SUBTOTAL(9,DG16:DG36) -> 0.069525 | DL15: =SUBTOTAL(9,DL16:DL36) -> 0 | DM15: =SUBTOTAL(9,DM16:DM36) -> 0.217725 | DN15: =SUBTOTAL(9,DN16:DN36) -> 0.36179 | DO15: =SUBTOTAL(9,DO16:DO36) -> 0.4188 | DP15: =SUBTOTAL(9,DP16:DP36) -> 0.43756 | DQ15: =SUBTOTAL(9,DQ16:DQ36) -> 0.45301 | DR15: =SUBTOTAL(9,DR16:DR36) -> 0.5126 | DS15: =SUBTOTAL(9,DS16:DS36) -> 0.522025 | ... EG15: =SUBTOTAL(9,EG16:EG36) -> 0.8667
A16: 1 | C16: Analisis Kebutuhan | F16: =SUBTOTAL(9,F17:F18) -> 0.0927 | AZ16: 0.0927 | BD16: 1 | BE16: =SUBTOTAL(9,BE17:BE18) -> 0.0927 | BF16: =SUBTOTAL(9,BF17:BF18) -> 0.0927 | BG16: =SUBTOTAL(9,BG17:BG18) -> 0.0927 | BH16: =SUBTOTAL(9,BH17:BH18) -> 0.0927 | BI16: =SUBTOTAL(9,BI17:BI18) -> 0 | BJ16: =SUBTOTAL(9,BJ17:BJ18) -> 0 | BM16: =SUBTOTAL(9,BM17:BM18) -> 0 | BN16: =SUBTOTAL(9,BN17:BN18) -> 0.04635 | BO16: =SUBTOTAL(9,BO17:BO18) -> 0.069525 | BP16: =SUBTOTAL(9,BP17:BP18) -> 0.0927 | BQ16: =SUBTOTAL(9,BQ17:BQ18) -> 0.0927 | BR16: =SUBTOTAL(9,BR17:BR18) -> 0.0927 | BS16: =SUBTOTAL(9,BS17:BS18) -> 0.0927 | BT16: =SUBTOTAL(9,BT17:BT18) -> 0.0927 | ... CH16: =SUBTOTAL(9,CH17:CH18) -> 0.0927 | CL16: =SUBTOTAL(9,CL17:CL18) -> 0 | CM16: =SUBTOTAL(9,CM17:CM18) -> 0 | CN16: =SUBTOTAL(9,CN17:CN18) -> 0 | CO16: =SUBTOTAL(9,CO17:CO18) -> 0 | CP16: =SUBTOTAL(9,CP17:CP18) -> 0 | CQ16: =SUBTOTAL(9,CQ17:CQ18) -> 0 | CR16: =SUBTOTAL(9,CR17:CR18) -> 0 | CS16: =SUBTOTAL(9,CS17:CS18) -> 0 | ... DG16: =SUBTOTAL(9,DG17:DG18) -> 0 | DL16: =SUBTOTAL(9,DL17:DL18) -> 0 | DM16: =SUBTOTAL(9,DM17:DM18) -> 0.069525 | DN16: =SUBTOTAL(9,DN17:DN18) -> 0.0927 | DO16: =SUBTOTAL(9,DO17:DO18) -> 0.0927 | DP16: =SUBTOTAL(9,DP17:DP18) -> 0.0927 | DQ16: =SUBTOTAL(9,DQ17:DQ18) -> 0.0927 | DR16: =SUBTOTAL(9,DR17:DR18) -> 0.0927 | DS16: =SUBTOTAL(9,DS17:DS18) -> 0.0927 | ... EG16: =SUBTOTAL(9,EG17:EG18) -> 0.0927
A17: 1.a | B17: W2026I-DNGF-EM-100-PRD-SPC-0001 | C17: Dokumentasi BRD | F17: 0.04 | H17: 46113 | J17: 46113 | K17: =H17+((O17-H17)*0.5) -> 46118 | M17: 46114 | O17: =H17+((W17-H17)*0.5) -> 46123 | Q17: 46118 | S17: =O17+((W17-O17)*0.5) -> 46128 | U17: 46125 | W17: 46133 | Y17: 46131 | AE17: =AN17 -> 0.04 | AG17: =IF(AND($Y17<>0,$Y17<=$BL$6),$Y$12,IF(AND($U17<>0,$U17<=$BL$6),$U$12,IF(AND($Q17<>0,$Q17<=$BL$6),$Q$12,IF(AND($M17<>0,$M17<=$BL$6),$M$12,IF(AND($J17<>0,$J17<=$BL$6),$J$12,0))))) -> 1 | AH17: =AI17-AG17 -> 0 | AI17: =IF(AND($Y17<>0,$Y17<=$BL$5),$Y$12,IF(AND($U17<>0,$U17<=$BL$5),$U$12,IF(AND($Q17<>0,$Q17<=$BL$5),$Q$12,IF(AND($M17<>0,$M17<=$BL$5),$M$12,IF(AND($J17<>0,$J17<=$BL$5),$J$12,0))))) -> 1 | AJ17: =IF(AND($W17<>0,$W17<=$BL$5),$W$12,IF(AND($S17<>0,$S17<=$BL$5),$S$12,IF(AND(#REF!<>0,#REF!<=$BL$5),$O$12,IF(AND($K17<>0,$K17<=$BL$5),$K$12,IF(AND($H17<>0,$H17<=$BL$5),$H$12,0))))) -> 1 | AK17: =IF(AND($X17<>0,$X17<=$BL$5),$X$12,IF(AND($T17<>0,$T17<=$BL$5),$T$12,IF(AND($P17<>0,$P17<=$BL$5),$P$12,IF(AND($L17<>0,$L17<=$BL$5),$L$12,IF(AND($I17<>0,$I17<=$BL$5),$I$12,0))))) -> 0 | AL17: =AI17-AJ17 -> 0 | AM17: =AI17-AK17 -> 1 | AN17: =AI17*F17 -> 0.04 | AO17: =AJ17*F17 -> 0.04 | AP17: =AK17*F17 -> 0 | AQ17: =AN17-AO17 -> 0 | AZ17: 0.04 | BD17: 1.a | BE17: =AG17*F17 -> 0.04 | BF17: =AI17*F17 -> 0.04 | BG17: =IF(AND($W17<>0,$W17<=$BL$6),$W$12,IF(AND($S17<>0,$S17<=$BL$6),$S$12,IF(AND($O17<>0,$O17<=$BL$6),$O$12,IF(AND($K17<>0,$K17<=$BL$6),$K$12,IF(AND($H17<>0,$H17<=$BL$6),$H$12,0)))))*$F17 -> 0.04 | BH17: =IF(AND($W17<>0,$W17<=$BL$5),$W$12,IF(AND($S17<>0,$S17<=$BL$5),$S$12,IF(AND($O17<>0,$O17<=$BL$5),$O$12,IF(AND($K17<>0,$K17<=$BL$5),$K$12,IF(AND($H17<>0,$H17<=$BL$5),$H$12,0)))))*$F17 -> 0.04 | BI17: =IF(AND($X17<>0,$X17<=$BL$6),$X$12,IF(AND($T17<>0,$T17<=$BL$6),$T$12,IF(AND($P17<>0,$P17<=$BL$6),$P$12,IF(AND($L17<>0,$L17<=$BL$6),$L$12,IF(AND($I17<>0,$I17<=$BL$6),$I$12,0)))))*$F17 -> 0 | BJ17: =IF(AND($X17<>0,$X17<=$BL$5),$X$12,IF(AND($T17<>0,$T17<=$BL$5),$T$12,IF(AND($P17<>0,$P17<=$BL$5),$P$12,IF(AND($L17<>0,$L17<=$BL$5),$L$12,IF(AND($I17<>0,$I17<=$BL$5),$I$12,0)))))*$F17 -> 0 | BM17: 0 | BN17: =IF(AND($W17<>0,$W17<=BN$12),$W$12*$F17,IF(AND($S17<>0,$S17<=BN$12),$S$12*$F17,IF(AND($O17<>0,$O17<=BN$12),$O$12*$F17,IF(AND($K17<>0,$K17<=BN$12),$K$12*$F17,IF(AND($H17<>0,$H17<=BN$12),$H$12*$F17,0))))) -> 0.02 | BO17: =IF(AND($W17<>0,$W17<=BO$12),$W$12*$F17,IF(AND($S17<>0,$S17<=BO$12),$S$12*$F17,IF(AND($O17<>0,$O17<=BO$12),$O$12*$F17,IF(AND($K17<>0,$K17<=BO$12),$K$12*$F17,IF(AND($H17<>0,$H17<=BO$12),$H$12*$F17,0))))) -> 0.03 | BP17: =IF(AND($W17<>0,$W17<=BP$12),$W$12*$F17,IF(AND($S17<>0,$S17<=BP$12),$S$12*$F17,IF(AND($O17<>0,$O17<=BP$12),$O$12*$F17,IF(AND($K17<>0,$K17<=BP$12),$K$12*$F17,IF(AND($H17<>0,$H17<=BP$12),$H$12*$F17,0))))) -> 0.04 | BQ17: =IF(AND($W17<>0,$W17<=BQ$12),$W$12*$F17,IF(AND($S17<>0,$S17<=BQ$12),$S$12*$F17,IF(AND($O17<>0,$O17<=BQ$12),$O$12*$F17,IF(AND($K17<>0,$K17<=BQ$12),$K$12*$F17,IF(AND($H17<>0,$H17<=BQ$12),$H$12*$F17,0))))) -> 0.04 | BR17: =IF(AND($W17<>0,$W17<=BR$12),$W$12*$F17,IF(AND($S17<>0,$S17<=BR$12),$S$12*$F17,IF(AND($O17<>0,$O17<=BR$12),$O$12*$F17,IF(AND($K17<>0,$K17<=BR$12),$K$12*$F17,IF(AND($H17<>0,$H17<=BR$12),$H$12*$F17,0))))) -> 0.04 | BS17: =IF(AND($W17<>0,$W17<=BS$12),$W$12*$F17,IF(AND($S17<>0,$S17<=BS$12),$S$12*$F17,IF(AND($O17<>0,$O17<=BS$12),$O$12*$F17,IF(AND($K17<>0,$K17<=BS$12),$K$12*$F17,IF(AND($H17<>0,$H17<=BS$12),$H$12*$F17,0))))) -> 0.04 | BT17: =IF(AND($W17<>0,$W17<=BT$12),$W$12*$F17,IF(AND($S17<>0,$S17<=BT$12),$S$12*$F17,IF(AND($O17<>0,$O17<=BT$12),$O$12*$F17,IF(AND($K17<>0,$K17<=BT$12),$K$12*$F17,IF(AND($H17<>0,$H17<=BT$12),$H$12*$F17,0))))) -> 0.04 | BU17: =IF(AND($W17<>0,$W17<=BU$12),$W$12*$F17,IF(AND($S17<>0,$S17<=BU$12),$S$12*$F17,IF(AND($O17<>0,$O17<=BU$12),$O$12*$F17,IF(AND($K17<>0,$K17<=BU$12),$K$12*$F17,IF(AND($H17<>0,$H17<=BU$12),$H$12*$F17,0))))) -> 0.04 | ... CH17: =IF(AND($W17<>0,$W17<=CH$12),$W$12*$F17,IF(AND($S17<>0,$S17<=CH$12),$S$12*$F17,IF(AND($O17<>0,$O17<=CH$12),$O$12*$F17,IF(AND($K17<>0,$K17<=CH$12),$K$12*$F17,IF(AND($H17<>0,$H17<=CH$12),$H$12*$F17,0))))) -> 0.04 | CL17: 0 | CM17: =IF(AND($X17<>0,$X17<=CM$12),$X$12*$F17,IF(AND($T17<>0,$T17<=CM$12),$T$12*$F17,IF(AND($P17<>0,$P17<=CM$12),$P$12*$F17,IF(AND($L17<>0,$L17<=CM$12),$L$12*$F17,IF(AND($I17<>0,$I17<=CM$12),$I$12*$F17,0))))) -> 0 | CN17: =IF(AND($X17<>0,$X17<=CN$12),$X$12*$F17,IF(AND($T17<>0,$T17<=CN$12),$T$12*$F17,IF(AND($P17<>0,$P17<=CN$12),$P$12*$F17,IF(AND($L17<>0,$L17<=CN$12),$L$12*$F17,IF(AND($I17<>0,$I17<=CN$12),$I$12*$F17,0))))) -> 0 | CO17: =IF(AND($X17<>0,$X17<=CO$12),$X$12*$F17,IF(AND($T17<>0,$T17<=CO$12),$T$12*$F17,IF(AND($P17<>0,$P17<=CO$12),$P$12*$F17,IF(AND($L17<>0,$L17<=CO$12),$L$12*$F17,IF(AND($I17<>0,$I17<=CO$12),$I$12*$F17,0))))) -> 0 | CP17: =IF(AND($X17<>0,$X17<=CP$12),$X$12*$F17,IF(AND($T17<>0,$T17<=CP$12),$T$12*$F17,IF(AND($P17<>0,$P17<=CP$12),$P$12*$F17,IF(AND($L17<>0,$L17<=CP$12),$L$12*$F17,IF(AND($I17<>0,$I17<=CP$12),$I$12*$F17,0))))) -> 0 | CQ17: =IF(AND($X17<>0,$X17<=CQ$12),$X$12*$F17,IF(AND($T17<>0,$T17<=CQ$12),$T$12*$F17,IF(AND($P17<>0,$P17<=CQ$12),$P$12*$F17,IF(AND($L17<>0,$L17<=CQ$12),$L$12*$F17,IF(AND($I17<>0,$I17<=CQ$12),$I$12*$F17,0))))) -> 0 | CR17: =IF(AND($X17<>0,$X17<=CR$12),$X$12*$F17,IF(AND($T17<>0,$T17<=CR$12),$T$12*$F17,IF(AND($P17<>0,$P17<=CR$12),$P$12*$F17,IF(AND($L17<>0,$L17<=CR$12),$L$12*$F17,IF(AND($I17<>0,$I17<=CR$12),$I$12*$F17,0))))) -> 0 | CS17: =IF(AND($X17<>0,$X17<=CS$12),$X$12*$F17,IF(AND($T17<>0,$T17<=CS$12),$T$12*$F17,IF(AND($P17<>0,$P17<=CS$12),$P$12*$F17,IF(AND($L17<>0,$L17<=CS$12),$L$12*$F17,IF(AND($I17<>0,$I17<=CS$12),$I$12*$F17,0))))) -> 0 | CT17: =IF(AND($X17<>0,$X17<=CT$12),$X$12*$F17,IF(AND($T17<>0,$T17<=CT$12),$T$12*$F17,IF(AND($P17<>0,$P17<=CT$12),$P$12*$F17,IF(AND($L17<>0,$L17<=CT$12),$L$12*$F17,IF(AND($I17<>0,$I17<=CT$12),$I$12*$F17,0))))) -> 0 | ... DG17: =IF(AND($X17<>0,$X17<=DG$12),$X$12*$F17,IF(AND($T17<>0,$T17<=DG$12),$T$12*$F17,IF(AND($P17<>0,$P17<=DG$12),$P$12*$F17,IF(AND($L17<>0,$L17<=DG$12),$L$12*$F17,IF(AND($I17<>0,$I17<=DG$12),$I$12*$F17,0))))) -> 0 | DL17: 0 | DM17: =IF(AND($Y17<>0,$Y17<=DM$12),$Y$12*$F17,IF(AND($U17<>0,$U17<=DM$12),$U$12*$F17,IF(AND($Q17<>0,$Q17<=DM$12),$Q$12*$F17,IF(AND($M17<>0,$M17<=DM$12),$M$12*$F17,IF(AND($J17<>0,$J17<=DM$12),$J$12*$F17,0))))) -> 0.03 | DN17: =IF(AND($Y17<>0,$Y17<=DN$12),$Y$12*$F17,IF(AND($U17<>0,$U17<=DN$12),$U$12*$F17,IF(AND($Q17<>0,$Q17<=DN$12),$Q$12*$F17,IF(AND($M17<>0,$M17<=DN$12),$M$12*$F17,IF(AND($J17<>0,$J17<=DN$12),$J$12*$F17,0))))) -> 0.04 | DO17: =IF(AND($Y17<>0,$Y17<=DO$12),$Y$12*$F17,IF(AND($U17<>0,$U17<=DO$12),$U$12*$F17,IF(AND($Q17<>0,$Q17<=DO$12),$Q$12*$F17,IF(AND($M17<>0,$M17<=DO$12),$M$12*$F17,IF(AND($J17<>0,$J17<=DO$12),$J$12*$F17,0))))) -> 0.04 | DP17: =IF(AND($Y17<>0,$Y17<=DP$12),$Y$12*$F17,IF(AND($U17<>0,$U17<=DP$12),$U$12*$F17,IF(AND($Q17<>0,$Q17<=DP$12),$Q$12*$F17,IF(AND($M17<>0,$M17<=DP$12),$M$12*$F17,IF(AND($J17<>0,$J17<=DP$12),$J$12*$F17,0))))) -> 0.04 | DQ17: =IF(AND($Y17<>0,$Y17<=DQ$12),$Y$12*$F17,IF(AND($U17<>0,$U17<=DQ$12),$U$12*$F17,IF(AND($Q17<>0,$Q17<=DQ$12),$Q$12*$F17,IF(AND($M17<>0,$M17<=DQ$12),$M$12*$F17,IF(AND($J17<>0,$J17<=DQ$12),$J$12*$F17,0))))) -> 0.04 | DR17: =IF(AND($Y17<>0,$Y17<=DR$12),$Y$12*$F17,IF(AND($U17<>0,$U17<=DR$12),$U$12*$F17,IF(AND($Q17<>0,$Q17<=DR$12),$Q$12*$F17,IF(AND($M17<>0,$M17<=DR$12),$M$12*$F17,IF(AND($J17<>0,$J17<=DR$12),$J$12*$F17,0))))) -> 0.04 | DS17: =IF(AND($Y17<>0,$Y17<=DS$12),$Y$12*$F17,IF(AND($U17<>0,$U17<=DS$12),$U$12*$F17,IF(AND($Q17<>0,$Q17<=DS$12),$Q$12*$F17,IF(AND($M17<>0,$M17<=DS$12),$M$12*$F17,IF(AND($J17<>0,$J17<=DS$12),$J$12*$F17,0))))) -> 0.04 | DT17: =IF(AND($Y17<>0,$Y17<=DT$12),$Y$12*$F17,IF(AND($U17<>0,$U17<=DT$12),$U$12*$F17,IF(AND($Q17<>0,$Q17<=DT$12),$Q$12*$F17,IF(AND($M17<>0,$M17<=DT$12),$M$12*$F17,IF(AND($J17<>0,$J17<=DT$12),$J$12*$F17,0))))) -> 0.04 | ... EG17: =IF(AND($Y17<>0,$Y17<=EG$12),$Y$12*$F17,IF(AND($U17<>0,$U17<=EG$12),$U$12*$F17,IF(AND($Q17<>0,$Q17<=EG$12),$Q$12*$F17,IF(AND($M17<>0,$M17<=EG$12),$M$12*$F17,IF(AND($J17<>0,$J17<=EG$12),$J$12*$F17,0))))) -> 0.04
A18: 1.b | B18: W2026I-DNGF-EM-100-PRD-SPC-0002 | C18: Dokumentasi Awal Hasil Wawancara | F18: 0.0527 | H18: 46113 | J18: 46113 | K18: =H18+((O18-H18)*0.5) -> 46118 | M18: 46114 | O18: =H18+((W18-H18)*0.5) -> 46123 | Q18: 46118 | S18: =O18+((W18-O18)*0.5) -> 46128 | U18: 46125 | W18: 46133 | Y18: 46131 | AE18: =AN18 -> 0.0527 | AG18: =IF(AND($Y18<>0,$Y18<=$BL$6),$Y$12,IF(AND($U18<>0,$U18<=$BL$6),$U$12,IF(AND($Q18<>0,$Q18<=$BL$6),$Q$12,IF(AND($M18<>0,$M18<=$BL$6),$M$12,IF(AND($J18<>0,$J18<=$BL$6),$J$12,0))))) -> 1 | AH18: =AI18-AG18 -> 0 | AI18: =IF(AND($Y18<>0,$Y18<=$BL$5),$Y$12,IF(AND($U18<>0,$U18<=$BL$5),$U$12,IF(AND($Q18<>0,$Q18<=$BL$5),$Q$12,IF(AND($M18<>0,$M18<=$BL$5),$M$12,IF(AND($J18<>0,$J18<=$BL$5),$J$12,0))))) -> 1 | AJ18: =IF(AND($W18<>0,$W18<=$BL$5),$W$12,IF(AND($S18<>0,$S18<=$BL$5),$S$12,IF(AND($O18<>0,$O18<=$BL$5),$O$12,IF(AND($K18<>0,$K18<=$BL$5),$K$12,IF(AND($H18<>0,$H18<=$BL$5),$H$12,0))))) -> 1 | AK18: =IF(AND($X18<>0,$X18<=$BL$5),$X$12,IF(AND($T18<>0,$T18<=$BL$5),$T$12,IF(AND($P18<>0,$P18<=$BL$5),$P$12,IF(AND($L18<>0,$L18<=$BL$5),$L$12,IF(AND($I18<>0,$I18<=$BL$5),$I$12,0))))) -> 0 | AL18: =AI18-AJ18 -> 0 | AM18: =AI18-AK18 -> 1 | AN18: =AI18*F18 -> 0.0527 | AO18: =AJ18*F18 -> 0.0527 | AP18: =AK18*F18 -> 0 | AQ18: =AN18-AO18 -> 0 | AZ18: 0.0527 | BD18: 1.b | BE18: =AG18*F18 -> 0.0527 | BF18: =AI18*F18 -> 0.0527 | BG18: =IF(AND($W18<>0,$W18<=$BL$6),$W$12,IF(AND($S18<>0,$S18<=$BL$6),$S$12,IF(AND($O18<>0,$O18<=$BL$6),$O$12,IF(AND($K18<>0,$K18<=$BL$6),$K$12,IF(AND($H18<>0,$H18<=$BL$6),$H$12,0)))))*$F18 -> 0.0527 | BH18: =IF(AND($W18<>0,$W18<=$BL$5),$W$12,IF(AND($S18<>0,$S18<=$BL$5),$S$12,IF(AND($O18<>0,$O18<=$BL$5),$O$12,IF(AND($K18<>0,$K18<=$BL$5),$K$12,IF(AND($H18<>0,$H18<=$BL$5),$H$12,0)))))*$F18 -> 0.0527 | BI18: =IF(AND($X18<>0,$X18<=$BL$6),$X$12,IF(AND($T18<>0,$T18<=$BL$6),$T$12,IF(AND($P18<>0,$P18<=$BL$6),$P$12,IF(AND($L18<>0,$L18<=$BL$6),$L$12,IF(AND($I18<>0,$I18<=$BL$6),$I$12,0)))))*$F18 -> 0 | BJ18: =IF(AND($X18<>0,$X18<=$BL$5),$X$12,IF(AND($T18<>0,$T18<=$BL$5),$T$12,IF(AND($P18<>0,$P18<=$BL$5),$P$12,IF(AND($L18<>0,$L18<=$BL$5),$L$12,IF(AND($I18<>0,$I18<=$BL$5),$I$12,0)))))*$F18 -> 0 | BM18: 0 | BN18: =IF(AND($W18<>0,$W18<=BN$12),$W$12*$F18,IF(AND($S18<>0,$S18<=BN$12),$S$12*$F18,IF(AND($O18<>0,$O18<=BN$12),$O$12*$F18,IF(AND($K18<>0,$K18<=BN$12),$K$12*$F18,IF(AND($H18<>0,$H18<=BN$12),$H$12*$F18,0))))) -> 0.02635 | BO18: =IF(AND($W18<>0,$W18<=BO$12),$W$12*$F18,IF(AND($S18<>0,$S18<=BO$12),$S$12*$F18,IF(AND($O18<>0,$O18<=BO$12),$O$12*$F18,IF(AND($K18<>0,$K18<=BO$12),$K$12*$F18,IF(AND($H18<>0,$H18<=BO$12),$H$12*$F18,0))))) -> 0.039525 | BP18: =IF(AND($W18<>0,$W18<=BP$12),$W$12*$F18,IF(AND($S18<>0,$S18<=BP$12),$S$12*$F18,IF(AND($O18<>0,$O18<=BP$12),$O$12*$F18,IF(AND($K18<>0,$K18<=BP$12),$K$12*$F18,IF(AND($H18<>0,$H18<=BP$12),$H$12*$F18,0))))) -> 0.0527 | BQ18: =IF(AND($W18<>0,$W18<=BQ$12),$W$12*$F18,IF(AND($S18<>0,$S18<=BQ$12),$S$12*$F18,IF(AND($O18<>0,$O18<=BQ$12),$O$12*$F18,IF(AND($K18<>0,$K18<=BQ$12),$K$12*$F18,IF(AND($H18<>0,$H18<=BQ$12),$H$12*$F18,0))))) -> 0.0527 | BR18: =IF(AND($W18<>0,$W18<=BR$12),$W$12*$F18,IF(AND($S18<>0,$S18<=BR$12),$S$12*$F18,IF(AND($O18<>0,$O18<=BR$12),$O$12*$F18,IF(AND($K18<>0,$K18<=BR$12),$K$12*$F18,IF(AND($H18<>0,$H18<=BR$12),$H$12*$F18,0))))) -> 0.0527 | BS18: =IF(AND($W18<>0,$W18<=BS$12),$W$12*$F18,IF(AND($S18<>0,$S18<=BS$12),$S$12*$F18,IF(AND($O18<>0,$O18<=BS$12),$O$12*$F18,IF(AND($K18<>0,$K18<=BS$12),$K$12*$F18,IF(AND($H18<>0,$H18<=BS$12),$H$12*$F18,0))))) -> 0.0527 | BT18: =IF(AND($W18<>0,$W18<=BT$12),$W$12*$F18,IF(AND($S18<>0,$S18<=BT$12),$S$12*$F18,IF(AND($O18<>0,$O18<=BT$12),$O$12*$F18,IF(AND($K18<>0,$K18<=BT$12),$K$12*$F18,IF(AND($H18<>0,$H18<=BT$12),$H$12*$F18,0))))) -> 0.0527 | BU18: =IF(AND($W18<>0,$W18<=BU$12),$W$12*$F18,IF(AND($S18<>0,$S18<=BU$12),$S$12*$F18,IF(AND($O18<>0,$O18<=BU$12),$O$12*$F18,IF(AND($K18<>0,$K18<=BU$12),$K$12*$F18,IF(AND($H18<>0,$H18<=BU$12),$H$12*$F18,0))))) -> 0.0527 | ... CH18: =IF(AND($W18<>0,$W18<=CH$12),$W$12*$F18,IF(AND($S18<>0,$S18<=CH$12),$S$12*$F18,IF(AND($O18<>0,$O18<=CH$12),$O$12*$F18,IF(AND($K18<>0,$K18<=CH$12),$K$12*$F18,IF(AND($H18<>0,$H18<=CH$12),$H$12*$F18,0))))) -> 0.0527 | CL18: 0 | CM18: =IF(AND($X18<>0,$X18<=CM$12),$X$12*$F18,IF(AND($T18<>0,$T18<=CM$12),$T$12*$F18,IF(AND($P18<>0,$P18<=CM$12),$P$12*$F18,IF(AND($L18<>0,$L18<=CM$12),$L$12*$F18,IF(AND($I18<>0,$I18<=CM$12),$I$12*$F18,0))))) -> 0 | CN18: =IF(AND($X18<>0,$X18<=CN$12),$X$12*$F18,IF(AND($T18<>0,$T18<=CN$12),$T$12*$F18,IF(AND($P18<>0,$P18<=CN$12),$P$12*$F18,IF(AND($L18<>0,$L18<=CN$12),$L$12*$F18,IF(AND($I18<>0,$I18<=CN$12),$I$12*$F18,0))))) -> 0 | CO18: =IF(AND($X18<>0,$X18<=CO$12),$X$12*$F18,IF(AND($T18<>0,$T18<=CO$12),$T$12*$F18,IF(AND($P18<>0,$P18<=CO$12),$P$12*$F18,IF(AND($L18<>0,$L18<=CO$12),$L$12*$F18,IF(AND($I18<>0,$I18<=CO$12),$I$12*$F18,0))))) -> 0 | CP18: =IF(AND($X18<>0,$X18<=CP$12),$X$12*$F18,IF(AND($T18<>0,$T18<=CP$12),$T$12*$F18,IF(AND($P18<>0,$P18<=CP$12),$P$12*$F18,IF(AND($L18<>0,$L18<=CP$12),$L$12*$F18,IF(AND($I18<>0,$I18<=CP$12),$I$12*$F18,0))))) -> 0 | CQ18: =IF(AND($X18<>0,$X18<=CQ$12),$X$12*$F18,IF(AND($T18<>0,$T18<=CQ$12),$T$12*$F18,IF(AND($P18<>0,$P18<=CQ$12),$P$12*$F18,IF(AND($L18<>0,$L18<=CQ$12),$L$12*$F18,IF(AND($I18<>0,$I18<=CQ$12),$I$12*$F18,0))))) -> 0 | CR18: =IF(AND($X18<>0,$X18<=CR$12),$X$12*$F18,IF(AND($T18<>0,$T18<=CR$12),$T$12*$F18,IF(AND($P18<>0,$P18<=CR$12),$P$12*$F18,IF(AND($L18<>0,$L18<=CR$12),$L$12*$F18,IF(AND($I18<>0,$I18<=CR$12),$I$12*$F18,0))))) -> 0 | CS18: =IF(AND($X18<>0,$X18<=CS$12),$X$12*$F18,IF(AND($T18<>0,$T18<=CS$12),$T$12*$F18,IF(AND($P18<>0,$P18<=CS$12),$P$12*$F18,IF(AND($L18<>0,$L18<=CS$12),$L$12*$F18,IF(AND($I18<>0,$I18<=CS$12),$I$12*$F18,0))))) -> 0 | CT18: =IF(AND($X18<>0,$X18<=CT$12),$X$12*$F18,IF(AND($T18<>0,$T18<=CT$12),$T$12*$F18,IF(AND($P18<>0,$P18<=CT$12),$P$12*$F18,IF(AND($L18<>0,$L18<=CT$12),$L$12*$F18,IF(AND($I18<>0,$I18<=CT$12),$I$12*$F18,0))))) -> 0 | ... DG18: =IF(AND($X18<>0,$X18<=DG$12),$X$12*$F18,IF(AND($T18<>0,$T18<=DG$12),$T$12*$F18,IF(AND($P18<>0,$P18<=DG$12),$P$12*$F18,IF(AND($L18<>0,$L18<=DG$12),$L$12*$F18,IF(AND($I18<>0,$I18<=DG$12),$I$12*$F18,0))))) -> 0 | DL18: 0 | DM18: =IF(AND($Y18<>0,$Y18<=DM$12),$Y$12*$F18,IF(AND($U18<>0,$U18<=DM$12),$U$12*$F18,IF(AND($Q18<>0,$Q18<=DM$12),$Q$12*$F18,IF(AND($M18<>0,$M18<=DM$12),$M$12*$F18,IF(AND($J18<>0,$J18<=DM$12),$J$12*$F18,0))))) -> 0.039525 | DN18: =IF(AND($Y18<>0,$Y18<=DN$12),$Y$12*$F18,IF(AND($U18<>0,$U18<=DN$12),$U$12*$F18,IF(AND($Q18<>0,$Q18<=DN$12),$Q$12*$F18,IF(AND($M18<>0,$M18<=DN$12),$M$12*$F18,IF(AND($J18<>0,$J18<=DN$12),$J$12*$F18,0))))) -> 0.0527 | DO18: =IF(AND($Y18<>0,$Y18<=DO$12),$Y$12*$F18,IF(AND($U18<>0,$U18<=DO$12),$U$12*$F18,IF(AND($Q18<>0,$Q18<=DO$12),$Q$12*$F18,IF(AND($M18<>0,$M18<=DO$12),$M$12*$F18,IF(AND($J18<>0,$J18<=DO$12),$J$12*$F18,0))))) -> 0.0527 | DP18: =IF(AND($Y18<>0,$Y18<=DP$12),$Y$12*$F18,IF(AND($U18<>0,$U18<=DP$12),$U$12*$F18,IF(AND($Q18<>0,$Q18<=DP$12),$Q$12*$F18,IF(AND($M18<>0,$M18<=DP$12),$M$12*$F18,IF(AND($J18<>0,$J18<=DP$12),$J$12*$F18,0))))) -> 0.0527 | DQ18: =IF(AND($Y18<>0,$Y18<=DQ$12),$Y$12*$F18,IF(AND($U18<>0,$U18<=DQ$12),$U$12*$F18,IF(AND($Q18<>0,$Q18<=DQ$12),$Q$12*$F18,IF(AND($M18<>0,$M18<=DQ$12),$M$12*$F18,IF(AND($J18<>0,$J18<=DQ$12),$J$12*$F18,0))))) -> 0.0527 | DR18: =IF(AND($Y18<>0,$Y18<=DR$12),$Y$12*$F18,IF(AND($U18<>0,$U18<=DR$12),$U$12*$F18,IF(AND($Q18<>0,$Q18<=DR$12),$Q$12*$F18,IF(AND($M18<>0,$M18<=DR$12),$M$12*$F18,IF(AND($J18<>0,$J18<=DR$12),$J$12*$F18,0))))) -> 0.0527 | DS18: =IF(AND($Y18<>0,$Y18<=DS$12),$Y$12*$F18,IF(AND($U18<>0,$U18<=DS$12),$U$12*$F18,IF(AND($Q18<>0,$Q18<=DS$12),$Q$12*$F18,IF(AND($M18<>0,$M18<=DS$12),$M$12*$F18,IF(AND($J18<>0,$J18<=DS$12),$J$12*$F18,0))))) -> 0.0527 | DT18: =IF(AND($Y18<>0,$Y18<=DT$12),$Y$12*$F18,IF(AND($U18<>0,$U18<=DT$12),$U$12*$F18,IF(AND($Q18<>0,$Q18<=DT$12),$Q$12*$F18,IF(AND($M18<>0,$M18<=DT$12),$M$12*$F18,IF(AND($J18<>0,$J18<=DT$12),$J$12*$F18,0))))) -> 0.0527 | ... EG18: =IF(AND($Y18<>0,$Y18<=EG$12),$Y$12*$F18,IF(AND($U18<>0,$U18<=EG$12),$U$12*$F18,IF(AND($Q18<>0,$Q18<=EG$12),$Q$12*$F18,IF(AND($M18<>0,$M18<=EG$12),$M$12*$F18,IF(AND($J18<>0,$J18<=EG$12),$J$12*$F18,0))))) -> 0.0527
A19: 2 | C19: Pengadaan | F19: =SUBTOTAL(9,F20) -> 0.0515 | AZ19: 0 | BD19: 2 | BE19: =SUBTOTAL(9,BE20) -> 0 | BF19: =SUBTOTAL(9,BF20) -> 0 | BG19: =SUBTOTAL(9,BG20) -> 0.0515 | BH19: =SUBTOTAL(9,BH20) -> 0.0515 | BI19: =SUBTOTAL(9,BI20) -> 0 | BJ19: =SUBTOTAL(9,BJ20) -> 0 | BM19: =SUBTOTAL(9,BM20) -> 0 | BN19: =SUBTOTAL(9,BN20) -> 0 | BO19: =SUBTOTAL(9,BO20) -> 0 | BP19: =SUBTOTAL(9,BP20) -> 0 | BQ19: =SUBTOTAL(9,BQ20) -> 0 | BR19: =SUBTOTAL(9,BR20) -> 0 | BS19: =SUBTOTAL(9,BS20) -> 0.002575 | BT19: =SUBTOTAL(9,BT20) -> 0.02575 | ... CH19: =SUBTOTAL(9,CH20) -> 0.0515 | CL19: =SUBTOTAL(9,CL20) -> 0 | CM19: =SUBTOTAL(9,CM20) -> 0 | CN19: =SUBTOTAL(9,CN20) -> 0 | CO19: =SUBTOTAL(9,CO20) -> 0 | CP19: =SUBTOTAL(9,CP20) -> 0 | CQ19: =SUBTOTAL(9,CQ20) -> 0 | CR19: =SUBTOTAL(9,CR20) -> 0 | CS19: =SUBTOTAL(9,CS20) -> 0 | ... DG19: =SUBTOTAL(9,DG20) -> 0.038625 | DL19: =SUBTOTAL(9,DL20) -> 0 | DM19: =SUBTOTAL(9,DM20) -> 0 | DN19: =SUBTOTAL(9,DN20) -> 0 | DO19: =SUBTOTAL(9,DO20) -> 0 | DP19: =SUBTOTAL(9,DP20) -> 0 | DQ19: =SUBTOTAL(9,DQ20) -> 0 | DR19: =SUBTOTAL(9,DR20) -> 0 | DS19: =SUBTOTAL(9,DS20) -> 0 | ... EG19: =SUBTOTAL(9,EG20) -> 0
A20: 2.a | C20: Pengadaan Hardware | F20: 0.0515 | H20: 46159 | I20: 46210 | K20: =H20+((O20-H20)*0.5) -> 46162.5 | L20: 46210 | O20: =H20+((W20-H20)*0.5) -> 46166 | P20: 46210 | S20: =O20+((W20-O20)*0.5) -> 46169.5 | T20: 46210 | W20: 46173 | AE20: =AN20 -> 0 | AG20: =IF(AND($Y20<>0,$Y20<=$BL$6),$Y$12,IF(AND($U20<>0,$U20<=$BL$6),$U$12,IF(AND($Q20<>0,$Q20<=$BL$6),$Q$12,IF(AND($M20<>0,$M20<=$BL$6),$M$12,IF(AND($J20<>0,$J20<=$BL$6),$J$12,0))))) -> 0 | AH20: =AI20-AG20 -> 0 | AI20: =IF(AND($Y20<>0,$Y20<=$BL$5),$Y$12,IF(AND($U20<>0,$U20<=$BL$5),$U$12,IF(AND($Q20<>0,$Q20<=$BL$5),$Q$12,IF(AND($M20<>0,$M20<=$BL$5),$M$12,IF(AND($J20<>0,$J20<=$BL$5),$J$12,0))))) -> 0 | AJ20: =IF(AND($W20<>0,$W20<=$BL$5),$W$12,IF(AND($S20<>0,$S20<=$BL$5),$S$12,IF(AND($O20<>0,$O20<=$BL$5),$O$12,IF(AND($K20<>0,$K20<=$BL$5),$K$12,IF(AND($H20<>0,$H20<=$BL$5),$H$12,0))))) -> 1 | AK20: =IF(AND($X20<>0,$X20<=$BL$5),$X$12,IF(AND($T20<>0,$T20<=$BL$5),$T$12,IF(AND($P20<>0,$P20<=$BL$5),$P$12,IF(AND($L20<>0,$L20<=$BL$5),$L$12,IF(AND($I20<>0,$I20<=$BL$5),$I$12,0))))) -> 0 | AL20: =AI20-AJ20 -> -1 | AM20: =AI20-AK20 -> 0 | AN20: =AI20*F20 -> 0 | AO20: =AJ20*F20 -> 0.0515 | AP20: =AK20*F20 -> 0 | AQ20: =AN20-AO20 -> -0.0515 | AZ20: 0 | BD20: 2.a | BE20: =AG20*F20 -> 0 | BF20: =AI20*F20 -> 0 | BG20: =IF(AND($W20<>0,$W20<=$BL$6),$W$12,IF(AND($S20<>0,$S20<=$BL$6),$S$12,IF(AND($O20<>0,$O20<=$BL$6),$O$12,IF(AND($K20<>0,$K20<=$BL$6),$K$12,IF(AND($H20<>0,$H20<=$BL$6),$H$12,0)))))*$F20 -> 0.0515 | BH20: =IF(AND($W20<>0,$W20<=$BL$5),$W$12,IF(AND($S20<>0,$S20<=$BL$5),$S$12,IF(AND($O20<>0,$O20<=$BL$5),$O$12,IF(AND($K20<>0,$K20<=$BL$5),$K$12,IF(AND($H20<>0,$H20<=$BL$5),$H$12,0)))))*$F20 -> 0.0515 | BI20: =IF(AND($X20<>0,$X20<=$BL$6),$X$12,IF(AND($T20<>0,$T20<=$BL$6),$T$12,IF(AND($P20<>0,$P20<=$BL$6),$P$12,IF(AND($L20<>0,$L20<=$BL$6),$L$12,IF(AND($I20<>0,$I20<=$BL$6),$I$12,0)))))*$F20 -> 0 | BJ20: =IF(AND($X20<>0,$X20<=$BL$5),$X$12,IF(AND($T20<>0,$T20<=$BL$5),$T$12,IF(AND($P20<>0,$P20<=$BL$5),$P$12,IF(AND($L20<>0,$L20<=$BL$5),$L$12,IF(AND($I20<>0,$I20<=$BL$5),$I$12,0)))))*$F20 -> 0 | BM20: 0 | BN20: =IF(AND($W20<>0,$W20<=BN$12),$W$12*$F20,IF(AND($S20<>0,$S20<=BN$12),$S$12*$F20,IF(AND($O20<>0,$O20<=BN$12),$O$12*$F20,IF(AND($K20<>0,$K20<=BN$12),$K$12*$F20,IF(AND($H20<>0,$H20<=BN$12),$H$12*$F20,0))))) -> 0 | BO20: =IF(AND($W20<>0,$W20<=BO$12),$W$12*$F20,IF(AND($S20<>0,$S20<=BO$12),$S$12*$F20,IF(AND($O20<>0,$O20<=BO$12),$O$12*$F20,IF(AND($K20<>0,$K20<=BO$12),$K$12*$F20,IF(AND($H20<>0,$H20<=BO$12),$H$12*$F20,0))))) -> 0 | BP20: =IF(AND($W20<>0,$W20<=BP$12),$W$12*$F20,IF(AND($S20<>0,$S20<=BP$12),$S$12*$F20,IF(AND($O20<>0,$O20<=BP$12),$O$12*$F20,IF(AND($K20<>0,$K20<=BP$12),$K$12*$F20,IF(AND($H20<>0,$H20<=BP$12),$H$12*$F20,0))))) -> 0 | BQ20: =IF(AND($W20<>0,$W20<=BQ$12),$W$12*$F20,IF(AND($S20<>0,$S20<=BQ$12),$S$12*$F20,IF(AND($O20<>0,$O20<=BQ$12),$O$12*$F20,IF(AND($K20<>0,$K20<=BQ$12),$K$12*$F20,IF(AND($H20<>0,$H20<=BQ$12),$H$12*$F20,0))))) -> 0 | BR20: =IF(AND($W20<>0,$W20<=BR$12),$W$12*$F20,IF(AND($S20<>0,$S20<=BR$12),$S$12*$F20,IF(AND($O20<>0,$O20<=BR$12),$O$12*$F20,IF(AND($K20<>0,$K20<=BR$12),$K$12*$F20,IF(AND($H20<>0,$H20<=BR$12),$H$12*$F20,0))))) -> 0 | BS20: =IF(AND($W20<>0,$W20<=BS$12),$W$12*$F20,IF(AND($S20<>0,$S20<=BS$12),$S$12*$F20,IF(AND($O20<>0,$O20<=BS$12),$O$12*$F20,IF(AND($K20<>0,$K20<=BS$12),$K$12*$F20,IF(AND($H20<>0,$H20<=BS$12),$H$12*$F20,0))))) -> 0.002575 | BT20: =IF(AND($W20<>0,$W20<=BT$12),$W$12*$F20,IF(AND($S20<>0,$S20<=BT$12),$S$12*$F20,IF(AND($O20<>0,$O20<=BT$12),$O$12*$F20,IF(AND($K20<>0,$K20<=BT$12),$K$12*$F20,IF(AND($H20<>0,$H20<=BT$12),$H$12*$F20,0))))) -> 0.02575 | BU20: =IF(AND($W20<>0,$W20<=BU$12),$W$12*$F20,IF(AND($S20<>0,$S20<=BU$12),$S$12*$F20,IF(AND($O20<>0,$O20<=BU$12),$O$12*$F20,IF(AND($K20<>0,$K20<=BU$12),$K$12*$F20,IF(AND($H20<>0,$H20<=BU$12),$H$12*$F20,0))))) -> 0.0515 | ... CH20: =IF(AND($W20<>0,$W20<=CH$12),$W$12*$F20,IF(AND($S20<>0,$S20<=CH$12),$S$12*$F20,IF(AND($O20<>0,$O20<=CH$12),$O$12*$F20,IF(AND($K20<>0,$K20<=CH$12),$K$12*$F20,IF(AND($H20<>0,$H20<=CH$12),$H$12*$F20,0))))) -> 0.0515 | CL20: 0 | CM20: =IF(AND($X20<>0,$X20<=CM$12),$X$12*$F20,IF(AND($T20<>0,$T20<=CM$12),$T$12*$F20,IF(AND($P20<>0,$P20<=CM$12),$P$12*$F20,IF(AND($L20<>0,$L20<=CM$12),$L$12*$F20,IF(AND($I20<>0,$I20<=CM$12),$I$12*$F20,0))))) -> 0 | CN20: =IF(AND($X20<>0,$X20<=CN$12),$X$12*$F20,IF(AND($T20<>0,$T20<=CN$12),$T$12*$F20,IF(AND($P20<>0,$P20<=CN$12),$P$12*$F20,IF(AND($L20<>0,$L20<=CN$12),$L$12*$F20,IF(AND($I20<>0,$I20<=CN$12),$I$12*$F20,0))))) -> 0 | CO20: =IF(AND($X20<>0,$X20<=CO$12),$X$12*$F20,IF(AND($T20<>0,$T20<=CO$12),$T$12*$F20,IF(AND($P20<>0,$P20<=CO$12),$P$12*$F20,IF(AND($L20<>0,$L20<=CO$12),$L$12*$F20,IF(AND($I20<>0,$I20<=CO$12),$I$12*$F20,0))))) -> 0 | CP20: =IF(AND($X20<>0,$X20<=CP$12),$X$12*$F20,IF(AND($T20<>0,$T20<=CP$12),$T$12*$F20,IF(AND($P20<>0,$P20<=CP$12),$P$12*$F20,IF(AND($L20<>0,$L20<=CP$12),$L$12*$F20,IF(AND($I20<>0,$I20<=CP$12),$I$12*$F20,0))))) -> 0 | CQ20: =IF(AND($X20<>0,$X20<=CQ$12),$X$12*$F20,IF(AND($T20<>0,$T20<=CQ$12),$T$12*$F20,IF(AND($P20<>0,$P20<=CQ$12),$P$12*$F20,IF(AND($L20<>0,$L20<=CQ$12),$L$12*$F20,IF(AND($I20<>0,$I20<=CQ$12),$I$12*$F20,0))))) -> 0 | CR20: =IF(AND($X20<>0,$X20<=CR$12),$X$12*$F20,IF(AND($T20<>0,$T20<=CR$12),$T$12*$F20,IF(AND($P20<>0,$P20<=CR$12),$P$12*$F20,IF(AND($L20<>0,$L20<=CR$12),$L$12*$F20,IF(AND($I20<>0,$I20<=CR$12),$I$12*$F20,0))))) -> 0 | CS20: =IF(AND($X20<>0,$X20<=CS$12),$X$12*$F20,IF(AND($T20<>0,$T20<=CS$12),$T$12*$F20,IF(AND($P20<>0,$P20<=CS$12),$P$12*$F20,IF(AND($L20<>0,$L20<=CS$12),$L$12*$F20,IF(AND($I20<>0,$I20<=CS$12),$I$12*$F20,0))))) -> 0 | CT20: =IF(AND($X20<>0,$X20<=CT$12),$X$12*$F20,IF(AND($T20<>0,$T20<=CT$12),$T$12*$F20,IF(AND($P20<>0,$P20<=CT$12),$P$12*$F20,IF(AND($L20<>0,$L20<=CT$12),$L$12*$F20,IF(AND($I20<>0,$I20<=CT$12),$I$12*$F20,0))))) -> 0 | ... DG20: =IF(AND($X20<>0,$X20<=DG$12),$X$12*$F20,IF(AND($T20<>0,$T20<=DG$12),$T$12*$F20,IF(AND($P20<>0,$P20<=DG$12),$P$12*$F20,IF(AND($L20<>0,$L20<=DG$12),$L$12*$F20,IF(AND($I20<>0,$I20<=DG$12),$I$12*$F20,0))))) -> 0.038625 | DL20: 0 | DM20: =IF(AND($Y20<>0,$Y20<=DM$12),$Y$12*$F20,IF(AND($U20<>0,$U20<=DM$12),$U$12*$F20,IF(AND($Q20<>0,$Q20<=DM$12),$Q$12*$F20,IF(AND($M20<>0,$M20<=DM$12),$M$12*$F20,IF(AND($J20<>0,$J20<=DM$12),$J$12*$F20,0))))) -> 0 | DN20: =IF(AND($Y20<>0,$Y20<=DN$12),$Y$12*$F20,IF(AND($U20<>0,$U20<=DN$12),$U$12*$F20,IF(AND($Q20<>0,$Q20<=DN$12),$Q$12*$F20,IF(AND($M20<>0,$M20<=DN$12),$M$12*$F20,IF(AND($J20<>0,$J20<=DN$12),$J$12*$F20,0))))) -> 0 | DO20: =IF(AND($Y20<>0,$Y20<=DO$12),$Y$12*$F20,IF(AND($U20<>0,$U20<=DO$12),$U$12*$F20,IF(AND($Q20<>0,$Q20<=DO$12),$Q$12*$F20,IF(AND($M20<>0,$M20<=DO$12),$M$12*$F20,IF(AND($J20<>0,$J20<=DO$12),$J$12*$F20,0))))) -> 0 | DP20: =IF(AND($Y20<>0,$Y20<=DP$12),$Y$12*$F20,IF(AND($U20<>0,$U20<=DP$12),$U$12*$F20,IF(AND($Q20<>0,$Q20<=DP$12),$Q$12*$F20,IF(AND($M20<>0,$M20<=DP$12),$M$12*$F20,IF(AND($J20<>0,$J20<=DP$12),$J$12*$F20,0))))) -> 0 | DQ20: =IF(AND($Y20<>0,$Y20<=DQ$12),$Y$12*$F20,IF(AND($U20<>0,$U20<=DQ$12),$U$12*$F20,IF(AND($Q20<>0,$Q20<=DQ$12),$Q$12*$F20,IF(AND($M20<>0,$M20<=DQ$12),$M$12*$F20,IF(AND($J20<>0,$J20<=DQ$12),$J$12*$F20,0))))) -> 0 | DR20: =IF(AND($Y20<>0,$Y20<=DR$12),$Y$12*$F20,IF(AND($U20<>0,$U20<=DR$12),$U$12*$F20,IF(AND($Q20<>0,$Q20<=DR$12),$Q$12*$F20,IF(AND($M20<>0,$M20<=DR$12),$M$12*$F20,IF(AND($J20<>0,$J20<=DR$12),$J$12*$F20,0))))) -> 0 | DS20: =IF(AND($Y20<>0,$Y20<=DS$12),$Y$12*$F20,IF(AND($U20<>0,$U20<=DS$12),$U$12*$F20,IF(AND($Q20<>0,$Q20<=DS$12),$Q$12*$F20,IF(AND($M20<>0,$M20<=DS$12),$M$12*$F20,IF(AND($J20<>0,$J20<=DS$12),$J$12*$F20,0))))) -> 0 | DT20: =IF(AND($Y20<>0,$Y20<=DT$12),$Y$12*$F20,IF(AND($U20<>0,$U20<=DT$12),$U$12*$F20,IF(AND($Q20<>0,$Q20<=DT$12),$Q$12*$F20,IF(AND($M20<>0,$M20<=DT$12),$M$12*$F20,IF(AND($J20<>0,$J20<=DT$12),$J$12*$F20,0))))) -> 0 | ... EG20: =IF(AND($Y20<>0,$Y20<=EG$12),$Y$12*$F20,IF(AND($U20<>0,$U20<=EG$12),$U$12*$F20,IF(AND($Q20<>0,$Q20<=EG$12),$Q$12*$F20,IF(AND($M20<>0,$M20<=EG$12),$M$12*$F20,IF(AND($J20<>0,$J20<=EG$12),$J$12*$F20,0))))) -> 0
A21: 3 | C21: Desain UI/UX | F21: =SUBTOTAL(9,F22:F24) -> 0.1733 | AZ21: 0.1733 | BD21: 3 | BE21: =SUBTOTAL(9,BE22:BE24) -> 0.1733 | BF21: =SUBTOTAL(9,BF22:BF24) -> 0.1733 | BG21: =SUBTOTAL(9,BG22:BG24) -> 0.168925 | BH21: =SUBTOTAL(9,BH22:BH24) -> 0.1733 | BI21: =SUBTOTAL(9,BI22:BI24) -> 0 | BJ21: =SUBTOTAL(9,BJ22:BJ24) -> 0 | BM21: =SUBTOTAL(9,BM22:BM24) -> 0 | BN21: =SUBTOTAL(9,BN22:BN24) -> 0.010825 | BO21: =SUBTOTAL(9,BO22:BO24) -> 0.02165 | BP21: =SUBTOTAL(9,BP22:BP24) -> 0.032475 | BQ21: =SUBTOTAL(9,BQ22:BQ24) -> 0.048925 | BR21: =SUBTOTAL(9,BR22:BR24) -> 0.071425 | BS21: =SUBTOTAL(9,BS22:BS24) -> 0.09955 | BT21: =SUBTOTAL(9,BT22:BT24) -> 0.127675 | ... CH21: =SUBTOTAL(9,CH22:CH24) -> 0.1733 | CL21: =SUBTOTAL(9,CL22:CL24) -> 0 | CM21: =SUBTOTAL(9,CM22:CM24) -> 0 | CN21: =SUBTOTAL(9,CN22:CN24) -> 0 | CO21: =SUBTOTAL(9,CO22:CO24) -> 0 | CP21: =SUBTOTAL(9,CP22:CP24) -> 0 | CQ21: =SUBTOTAL(9,CQ22:CQ24) -> 0 | CR21: =SUBTOTAL(9,CR22:CR24) -> 0 | CS21: =SUBTOTAL(9,CS22:CS24) -> 0 | ... DG21: =SUBTOTAL(9,DG22:DG24) -> 0 | DL21: =SUBTOTAL(9,DL22:DL24) -> 0 | DM21: =SUBTOTAL(9,DM22:DM24) -> 0.10185 | DN21: =SUBTOTAL(9,DN22:DN24) -> 0.1733 | DO21: =SUBTOTAL(9,DO22:DO24) -> 0.1733 | DP21: =SUBTOTAL(9,DP22:DP24) -> 0.1733 | DQ21: =SUBTOTAL(9,DQ22:DQ24) -> 0.1733 | DR21: =SUBTOTAL(9,DR22:DR24) -> 0.1733 | DS21: =SUBTOTAL(9,DS22:DS24) -> 0.1733 | ... EG21: =SUBTOTAL(9,EG22:EG24) -> 0.1733
